Workbook

Sheet Cover
A1: 山雾咖啡 · 连锁咖啡财务模型
A2: finmodel-builder skill 的第二个行业实例（volume_price：门店×杯量×客单）| 数据与逻辑分离：改数只改 Meta!G | 万元
A4: Meta | B4: 数据层宽表——唯一取数源
A5: Assumptions | B5: 指标视图层（SUMIFS 取自 Meta）
A6: StoreCapex | B6: 门店批次折旧引擎
A7: IS | B7: 三表（倒挤现金勾稽）
A8: Dashboard | B8: 三下拉维度看板
A9: UE | B9: 单店单位经济（回本期）
A10: Checks | B10: 勾稽自检
A12: 速览 | C12: 2023 | D12: 2024 | E12: 2025 | F12: 2026 | G12: 2027
A13: 收入 | C13: =IS!C6 | D13: =IS!D6 | E13: =IS!E6 | F13: =IS!F6 | G13: =IS!G6
A14: 净利润 | C14: =IS!C18 | D14: =IS!D18 | E14: =IS!E18 | F14: =IS!F18 | G14: =IS!G18
A15: 期末现金 | C15: =BS!C12 | D15: =BS!D12 | E15: =BS!E12 | F15: =BS!F12 | G15: =BS!G12

Sheet Meta
A1: Meta · 数据层宽表（全模型唯一取数源）
A2: 字段：主体/业务线/地区/期间/场景(A实际·B预算)/指标/值/来源/备注 | 日常=按期灌数与维护来源；引擎与公式零改动
A3: entity | B3: segment | C3: region | D3: period | E3: scenario | F3: metric | G3: value | H3: source | I3: note
A4: GROUP | D4: 2023 | E4: ACTUAL | F4: stores | G4: 800 | H4: 门店系统 | I4: 期末门店数（家）
A5: GROUP | D5: 2023 | E5: ACTUAL | F5: daily_cups | G5: 350 | H5: POS 汇总 | I5: 日均杯量/店（杯）
A6: GROUP | D6: 2023 | E6: ACTUAL | F6: avg_ticket | G6: 15 | H6: POS 汇总 | I6: 客单价（元）
A7: GROUP | D7: 2023 | E7: ACTUAL | F7: retail_ratio | G7: 0.08 | H7: 假设初始化 | I7: 零售产品占现制比例
A8: GROUP | D8: 2023 | E8: ACTUAL | F8: cogs_rate | G8: 0.33 | H8: tsdata·A股餐饮校准 | I8: 原料成本率
A9: GROUP | D9: 2023 | E9: ACTUAL | F9: store_opex_m | G9: 6.8 | H9: tsdata·A股餐饮校准 | I9: 单店月运营成本（万）
A10: GROUP | D10: 2023 | E10: ACTUAL | F10: mkt_rate | G10: 0.085 | H10: tsdata·A股餐饮校准 | I10: 营销费率
A11: GROUP | D11: 2023 | E11: ACTUAL | F11: headcount_rd | G11: 25 | H11: 假设初始化 | I11: 研发编制（数字化）
A12: GROUP | D12: 2023 | E12: ACTUAL | F12: salary_rd | G12: 45 | H12: 假设初始化 | I12: 研发人均全成本（万/年）
A13: GROUP | D13: 2023 | E13: ACTUAL | F13: headcount_sales | G13: 40 | H13: 假设初始化 | I13: 销售市场编制
A14: GROUP | D14: 2023 | E14: ACTUAL | F14: salary_sales | G14: 40 | H14: 假设初始化 | I14: 销售人均全成本（万/年）
A15: GROUP | D15: 2023 | E15: ACTUAL | F15: headcount_gna | G15: 45 | H15: 假设初始化 | I15: 管理编制
... A25: GROUP | D25: 2023 | E25: ACTUAL | F25: open_store_fa | G25: 36000 | H25: 假设初始化 | I25: 期初门店资产原值（万）
A26: GROUP | C26: 一线 | D26: 2023 | E26: ACTUAL | F26: region_mix | G26: 0.45 | H26: 行业研究 | I26: 收入地区占比
A27: GROUP | C27: 新一线 | D27: 2023 | E27: ACTUAL | F27: region_mix | G27: 0.3 | H27: 行业研究 | I27: 收入地区占比
A28: GROUP | C28: 二线及以下 | D28: 2023 | E28: ACTUAL | F28: region_mix | G28: 0.18 | H28: 行业研究 | I28: 收入地区占比
A29: GROUP | C29: 海外 | D29: 2023 | E29: ACTUAL | F29: region_mix | G29: 0.07 | H29: 行业研究 | I29: 收入地区占比
A30: GROUP | D30: 2024 | E30: ACTUAL | F30: stores | G30: 1200 | H30: 门店系统 | I30: 期末门店数（家）
A31: GROUP | D31: 2024 | E31: ACTUAL | F31: daily_cups | G31: 400 | H31: POS 汇总 | I31: 日均杯量/店（杯）
A32: GROUP | D32: 2024 | E32: ACTUAL | F32: avg_ticket | G32: 15.5 | H32: POS 汇总 | I32: 客单价（元）
A33: GROUP | D33: 2024 | E33: ACTUAL | F33: retail_ratio | G33: 0.08 | H33: 假设初始化 | I33: 零售产品占现制比例
A34: GROUP | D34: 2024 | E34: ACTUAL | F34: cogs_rate | G34: 0.32 | H34: tsdata·A股餐饮校准 | I34: 原料成本率
A35: GROUP | D35: 2024 | E35: ACTUAL | F35: store_opex_m | G35: 7 | H35: tsdata·A股餐饮校准 | I35: 单店月运营成本（万）
A36: GROUP | D36: 2024 | E36: ACTUAL | F36: mkt_rate | G36: 0.075 | H36: tsdata·A股餐饮校准 | I36: 营销费率
A37: GROUP | D37: 2024 | E37: ACTUAL | F37: headcount_rd | G37: 35 | H37: 假设初始化 | I37: 研发编制（数字化）
A38: GROUP | D38: 2024 | E38: ACTUAL | F38: salary_rd | G38: 45 | H38: 假设初始化 | I38: 研发人均全成本（万/年）
A39: GROUP | D39: 2024 | E39: ACTUAL | F39: headcount_sales | G39: 55 | H39: 假设初始化 | I39: 销售市场编制
A40: GROUP | D40: 2024 | E40: ACTUAL | F40: salary_sales | G40: 40 | H40: 假设初始化 | I40: 销售人均全成本（万/年）
A41: GROUP | D41: 2024 | E41: ACTUAL | F41: headcount_gna | G41: 55 | H41: 假设初始化 | I41: 管理编制
... A51: GROUP | D51: 2024 | E51: ACTUAL | F51: open_store_fa | G51: 36000 | H51: 假设初始化 | I51: 期初门店资产原值（万）
A52: GROUP | C52: 一线 | D52: 2024 | E52: ACTUAL | F52: region_mix | G52: 0.42 | H52: 行业研究 | I52: 收入地区占比
A53: GROUP | C53: 新一线 | D53: 2024 | E53: ACTUAL | F53: region_mix | G53: 0.3 | H53: 行业研究 | I53: 收入地区占比
A54: GROUP | C54: 二线及以下 | D54: 2024 | E54: ACTUAL | F54: region_mix | G54: 0.21 | H54: 行业研究 | I54: 收入地区占比
A55: GROUP | C55: 海外 | D55: 2024 | E55: ACTUAL | F55: region_mix | G55: 0.07 | H55: 行业研究 | I55: 收入地区占比
A56: GROUP | D56: 2025 | E56: ACTUAL | F56: stores | G56: 1800 | H56: 门店系统 | I56: 期末门店数（家）
A57: GROUP | D57: 2025 | E57: ACTUAL | F57: daily_cups | G57: 450 | H57: POS 汇总 | I57: 日均杯量/店（杯）
A58: GROUP | D58: 2025 | E58: ACTUAL | F58: avg_ticket | G58: 16 | H58: POS 汇总 | I58: 客单价（元）
...

Sheet Assumptions
A1: 山雾咖啡 · 指标视图层
A2: 全部实时取自 Meta（SUMIFS）| 改数请改 Meta!G 列 | 万元
A3: 科目（万元） | B3: 备注 | C3: 2023 | D3: 2024 | E3: 2025 | F3: 2026 | G3: 2027
A4: ── 量×价 驱动 ──
A5: 期末门店数（家） | C5: =SUMIFS(Meta!$G$2:$G$400,Meta!$F$2:$F$400,"stores",Meta!$D$2:$D$400,C$3,Meta!$A$2:$A$400,"GROUP") | D5: =SUMIFS(Meta!$G$2:$G$400,Meta!$F$2:$F$400,"stores",Meta!$D$2:$D$400,D$3,Meta!$A$2:$A$400,"GROUP") | E5: =SUMIFS(Meta!$G$2:$G$400,Meta!$F$2:$F$400,"stores",Meta!$D$2:$D$400,E$3,Meta!$A$2:$A$400,"GROUP") | F5: =SUMIFS(Meta!$G$2:$G$400,Meta!$F$2:$F$400,"stores",Meta!$D$2:$D$400,F$3,Meta!$A$2:$A$400,"GROUP") | G5: =SUMIFS(Meta!$G$2:$G$400,Meta!$F$2:$F$400,"stores",Meta!$D$2:$D$400,G$3,Meta!$A$2:$A$400,"GROUP")
A6: 日均杯量/店（杯） | C6: =SUMIFS(Meta!$G$2:$G$400,Meta!$F$2:$F$400,"daily_cups",Meta!$D$2:$D$400,C$3,Meta!$A$2:$A$400,"GROUP") | D6: =SUMIFS(Meta!$G$2:$G$400,Meta!$F$2:$F$400,"daily_cups",Meta!$D$2:$D$400,D$3,Meta!$A$2:$A$400,"GROUP") | E6: =SUMIFS(Meta!$G$2:$G$400,Meta!$F$2:$F$400,"daily_cups",Meta!$D$2:$D$400,E$3,Meta!$A$2:$A$400,"GROUP") | F6: =SUMIFS(Meta!$G$2:$G$400,Meta!$F$2:$F$400,"daily_cups",Meta!$D$2:$D$400,F$3,Meta!$A$2:$A$400,"GROUP") | G6: =SUMIFS(Meta!$G$2:$G$400,Meta!$F$2:$F$400,"daily_cups",Meta!$D$2:$D$400,G$3,Meta!$A$2:$A$400,"GROUP")
A7: 客单价（元） | C7: =SUMIFS(Meta!$G$2:$G$400,Meta!$F$2:$F$400,"avg_ticket",Meta!$D$2:$D$400,C$3,Meta!$A$2:$A$400,"GROUP") | D7: =SUMIFS(Meta!$G$2:$G$400,Meta!$F$2:$F$400,"avg_ticket",Meta!$D$2:$D$400,D$3,Meta!$A$2:$A$400,"GROUP") | E7: =SUMIFS(Meta!$G$2:$G$400,Meta!$F$2:$F$400,"avg_ticket",Meta!$D$2:$D$400,E$3,Meta!$A$2:$A$400,"GROUP") | F7: =SUMIFS(Meta!$G$2:$G$400,Meta!$F$2:$F$400,"avg_ticket",Meta!$D$2:$D$400,F$3,Meta!$A$2:$A$400,"GROUP") | G7: =SUMIFS(Meta!$G$2:$G$400,Meta!$F$2:$F$400,"avg_ticket",Meta!$D$2:$D$400,G$3,Meta!$A$2:$A$400,"GROUP")
A8: 零售占现制比例 | C8: =SUMIFS(Meta!$G$2:$G$400,Meta!$F$2:$F$400,"retail_ratio",Meta!$D$2:$D$400,C$3,Meta!$A$2:$A$400,"GROUP") | D8: =SUMIFS(Meta!$G$2:$G$400,Meta!$F$2:$F$400,"retail_ratio",Meta!$D$2:$D$400,D$3,Meta!$A$2:$A$400,"GROUP") | E8: =SUMIFS(Meta!$G$2:$G$400,Meta!$F$2:$F$400,"retail_ratio",Meta!$D$2:$D$400,E$3,Meta!$A$2:$A$400,"GROUP") | F8: =SUMIFS(Meta!$G$2:$G$400,Meta!$F$2:$F$400,"retail_ratio",Meta!$D$2:$D$400,F$3,Meta!$A$2:$A$400,"GROUP") | G8: =SUMIFS(Meta!$G$2:$G$400,Meta!$F$2:$F$400,"retail_ratio",Meta!$D$2:$D$400,G$3,Meta!$A$2:$A$400,"GROUP")
A9: ── 成本 ──
A10: 原料成本率 | C10: =SUMIFS(Meta!$G$2:$G$400,Meta!$F$2:$F$400,"cogs_rate",Meta!$D$2:$D$400,C$3,Meta!$A$2:$A$400,"GROUP") | D10: =SUMIFS(Meta!$G$2:$G$400,Meta!$F$2:$F$400,"cogs_rate",Meta!$D$2:$D$400,D$3,Meta!$A$2:$A$400,"GROUP") | E10: =SUMIFS(Meta!$G$2:$G$400,Meta!$F$2:$F$400,"cogs_rate",Meta!$D$2:$D$400,E$3,Meta!$A$2:$A$400,"GROUP") | F10: =SUMIFS(Meta!$G$2:$G$400,Meta!$F$2:$F$400,"cogs_rate",Meta!$D$2:$D$400,F$3,Meta!$A$2:$A$400,"GROUP") | G10: =SUMIFS(Meta!$G$2:$G$400,Meta!$F$2:$F$400,"cogs_rate",Meta!$D$2:$D$400,G$3,Meta!$A$2:$A$400,"GROUP")
A11: 单店月运营（万） | C11: =SUMIFS(Meta!$G$2:$G$400,Meta!$F$2:$F$400,"store_opex_m",Meta!$D$2:$D$400,C$3,Meta!$A$2:$A$400,"GROUP") | D11: =SUMIFS(Meta!$G$2:$G$400,Meta!$F$2:$F$400,"store_opex_m",Meta!$D$2:$D$400,D$3,Meta!$A$2:$A$400,"GROUP") | E11: =SUMIFS(Meta!$G$2:$G$400,Meta!$F$2:$F$400,"store_opex_m",Meta!$D$2:$D$400,E$3,Meta!$A$2:$A$400,"GROUP") | F11: =SUMIFS(Meta!$G$2:$G$400,Meta!$F$2:$F$400,"store_opex_m",Meta!$D$2:$D$400,F$3,Meta!$A$2:$A$400,"GROUP") | G11: =SUMIFS(Meta!$G$2:$G$400,Meta!$F$2:$F$400,"store_opex_m",Meta!$D$2:$D$400,G$3,Meta!$A$2:$A$400,"GROUP")
A12: 营销费率 | C12: =SUMIFS(Meta!$G$2:$G$400,Meta!$F$2:$F$400,"mkt_rate",Meta!$D$2:$D$400,C$3,Meta!$A$2:$A$400,"GROUP") | D12: =SUMIFS(Meta!$G$2:$G$400,Meta!$F$2:$F$400,"mkt_rate",Meta!$D$2:$D$400,D$3,Meta!$A$2:$A$400,"GROUP") | E12: =SUMIFS(Meta!$G$2:$G$400,Meta!$F$2:$F$400,"mkt_rate",Meta!$D$2:$D$400,E$3,Meta!$A$2:$A$400,"GROUP") | F12: =SUMIFS(Meta!$G$2:$G$400,Meta!$F$2:$F$400,"mkt_rate",Meta!$D$2:$D$400,F$3,Meta!$A$2:$A$400,"GROUP") | G12: =SUMIFS(Meta!$G$2:$G$400,Meta!$F$2:$F$400,"mkt_rate",Meta!$D$2:$D$400,G$3,Meta!$A$2:$A$400,"GROUP")
A13: ── 总部与结构 ──
A14: 研发编制 | C14: =SUMIFS(Meta!$G$2:$G$400,Meta!$F$2:$F$400,"headcount_rd",Meta!$D$2:$D$400,C$3,Meta!$A$2:$A$400,"GROUP") | D14: =SUMIFS(Meta!$G$2:$G$400,Meta!$F$2:$F$400,"headcount_rd",Meta!$D$2:$D$400,D$3,Meta!$A$2:$A$400,"GROUP") | E14: =SUMIFS(Meta!$G$2:$G$400,Meta!$F$2:$F$400,"headcount_rd",Meta!$D$2:$D$400,E$3,Meta!$A$2:$A$400,"GROUP") | F14: =SUMIFS(Meta!$G$2:$G$400,Meta!$F$2:$F$400,"headcount_rd",Meta!$D$2:$D$400,F$3,Meta!$A$2:$A$400,"GROUP") | G14: =SUMIFS(Meta!$G$2:$G$400,Meta!$F$2:$F$400,"headcount_rd",Meta!$D$2:$D$400,G$3,Meta!$A$2:$A$400,"GROUP")
A15: 销售市场编制 | C15: =SUMIFS(Meta!$G$2:$G$400,Meta!$F$2:$F$400,"headcount_sales",Meta!$D$2:$D$400,C$3,Meta!$A$2:$A$400,"GROUP") | D15: =SUMIFS(Meta!$G$2:$G$400,Meta!$F$2:$F$400,"headcount_sales",Meta!$D$2:$D$400,D$3,Meta!$A$2:$A$400,"GROUP") | E15: =SUMIFS(Meta!$G$2:$G$400,Meta!$F$2:$F$400,"headcount_sales",Meta!$D$2:$D$400,E$3,Meta!$A$2:$A$400,"GROUP") | F15: =SUMIFS(Meta!$G$2:$G$400,Meta!$F$2:$F$400,"headcount_sales",Meta!$D$2:$D$400,F$3,Meta!$A$2:$A$400,"GROUP") | G15: =SUMIFS(Meta!$G$2:$G$400,Meta!$F$2:$F$400,"headcount_sales",Meta!$D$2:$D$400,G$3,Meta!$A$2:$A$400,"GROUP")
A16: 管理编制 | C16: =SUMIFS(Meta!$G$2:$G$400,Meta!$F$2:$F$400,"headcount_gna",Meta!$D$2:$D$400,C$3,Meta!$A$2:$A$400,"GROUP") | D16: =SUMIFS(Meta!$G$2:$G$400,Meta!$F$2:$F$400,"headcount_gna",Meta!$D$2:$D$400,D$3,Meta!$A$2:$A$400,"GROUP") | E16: =SUMIFS(Meta!$G$2:$G$400,Meta!$F$2:$F$400,"headcount_gna",Meta!$D$2:$D$400,E$3,Meta!$A$2:$A$400,"GROUP") | F16: =SUMIFS(Meta!$G$2:$G$400,Meta!$F$2:$F$400,"headcount_gna",Meta!$D$2:$D$400,F$3,Meta!$A$2:$A$400,"GROUP") | G16: =SUMIFS(Meta!$G$2:$G$400,Meta!$F$2:$F$400,"headcount_gna",Meta!$D$2:$D$400,G$3,Meta!$A$2:$A$400,"GROUP")
A17: 研发人均（万/年） | C17: =SUMIFS(Meta!$G$2:$G$400,Meta!$F$2:$F$400,"salary_rd",Meta!$D$2:$D$400,C$3,Meta!$A$2:$A$400,"GROUP") | D17: =SUMIFS(Meta!$G$2:$G$400,Meta!$F$2:$F$400,"salary_rd",Meta!$D$2:$D$400,D$3,Meta!$A$2:$A$400,"GROUP") | E17: =SUMIFS(Meta!$G$2:$G$400,Meta!$F$2:$F$400,"salary_rd",Meta!$D$2:$D$400,E$3,Meta!$A$2:$A$400,"GROUP") | F17: =SUMIFS(Meta!$G$2:$G$400,Meta!$F$2:$F$400,"salary_rd",Meta!$D$2:$D$400,F$3,Meta!$A$2:$A$400,"GROUP") | G17: =SUMIFS(Meta!$G$2:$G$400,Meta!$F$2:$F$400,"salary_rd",Meta!$D$2:$D$400,G$3,Meta!$A$2:$A$400,"GROUP")
A18: 销售人均（万/年） | C18: =SUMIFS(Meta!$G$2:$G$400,Meta!$F$2:$F$400,"salary_sales",Meta!$D$2:$D$400,C$3,Meta!$A$2:$A$400,"GROUP") | D18: =SUMIFS(Meta!$G$2:$G$400,Meta!$F$2:$F$400,"salary_sales",Meta!$D$2:$D$400,D$3,Meta!$A$2:$A$400,"GROUP") | E18: =SUMIFS(Meta!$G$2:$G$400,Meta!$F$2:$F$400,"salary_sales",Meta!$D$2:$D$400,E$3,Meta!$A$2:$A$400,"GROUP") | F18: =SUMIFS(Meta!$G$2:$G$400,Meta!$F$2:$F$400,"salary_sales",Meta!$D$2:$D$400,F$3,Meta!$A$2:$A$400,"GROUP") | G18: =SUMIFS(Meta!$G$2:$G$400,Meta!$F$2:$F$400,"salary_sales",Meta!$D$2:$D$400,G$3,Meta!$A$2:$A$400,"GROUP")
A19: 管理人均（万/年） | C19: =SUMIFS(Meta!$G$2:$G$400,Meta!$F$2:$F$400,"salary_gna",Meta!$D$2:$D$400,C$3,Meta!$A$2:$A$400,"GROUP") | D19: =SUMIFS(Meta!$G$2:$G$400,Meta!$F$2:$F$400,"salary_gna",Meta!$D$2:$D$400,D$3,Meta!$A$2:$A$400,"GROUP") | E19: =SUMIFS(Meta!$G$2:$G$400,Meta!$F$2:$F$400,"salary_gna",Meta!$D$2:$D$400,E$3,Meta!$A$2:$A$400,"GROUP") | F19: =SUMIFS(Meta!$G$2:$G$400,Meta!$F$2:$F$400,"salary_gna",Meta!$D$2:$D$400,F$3,Meta!$A$2:$A$400,"GROUP") | G19: =SUMIFS(Meta!$G$2:$G$400,Meta!$F$2:$F$400,"salary_gna",Meta!$D$2:$D$400,G$3,Meta!$A$2:$A$400,"GROUP")
A20: 单店投入（万） | C20: =SUMIFS(Meta!$G$2:$G$400,Meta!$F$2:$F$400,"capex_per_store",Meta!$D$2:$D$400,C$3,Meta!$A$2:$A$400,"GROUP") | D20: =SUMIFS(Meta!$G$2:$G$400,Meta!$F$2:$F$400,"capex_per_store",Meta!$D$2:$D$400,D$3,Meta!$A$2:$A$400,"GROUP") | E20: =SUMIFS(Meta!$G$2:$G$400,Meta!$F$2:$F$400,"capex_per_store",Meta!$D$2:$D$400,E$3,Meta!$A$2:$A$400,"GROUP") | F20: =SUMIFS(Meta!$G$2:$G$400,Meta!$F$2:$F$400,"capex_per_store",Meta!$D$2:$D$400,F$3,Meta!$A$2:$A$400,"GROUP") | G20: =SUMIFS(Meta!$G$2:$G$400,Meta!$F$2:$F$400,"capex_per_store",Meta!$D$2:$D$400,G$3,Meta!$A$2:$A$400,"GROUP")
A21: 所得税率 | C21: =SUMIFS(Meta!$G$2:$G$400,Meta!$F$2:$F$400,"tax_rate",Meta!$D$2:$D$400,C$3,Meta!$A$2:$A$400,"GROUP") | D21: =SUMIFS(Meta!$G$2:$G$400,Meta!$F$2:$F$400,"tax_rate",Meta!$D$2:$D$400,D$3,Meta!$A$2:$A$400,"GROUP") | E21: =SUMIFS(Meta!$G$2:$G$400,Meta!$F$2:$F$400,"tax_rate",Meta!$D$2:$D$400,E$3,Meta!$A$2:$A$400,"GROUP") | F21: =SUMIFS(Meta!$G$2:$G$400,Meta!$F$2:$F$400,"tax_rate",Meta!$D$2:$D$400,F$3,Meta!$A$2:$A$400,"GROUP") | G21: =SUMIFS(Meta!$G$2:$G$400,Meta!$F$2:$F$400,"tax_rate",Meta!$D$2:$D$400,G$3,Meta!$A$2:$A$400,"GROUP")
A22: 应收账期（天） | C22: =SUMIFS(Meta!$G$2:$G$400,Meta!$F$2:$F$400,"dso_days",Meta!$D$2:$D$400,C$3,Meta!$A$2:$A$400,"GROUP") | D22: =SUMIFS(Meta!$G$2:$G$400,Meta!$F$2:$F$400,"dso_days",Meta!$D$2:$D$400,D$3,Meta!$A$2:$A$400,"GROUP") | E22: =SUMIFS(Meta!$G$2:$G$400,Meta!$F$2:$F$400,"dso_days",Meta!$D$2:$D$400,E$3,Meta!$A$2:$A$400,"GROUP") | F22: =SUMIFS(Meta!$G$2:$G$400,Meta!$F$2:$F$400,"dso_days",Meta!$D$2:$D$400,F$3,Meta!$A$2:$A$400,"GROUP") | G22: =SUMIFS(Meta!$G$2:$G$400,Meta!$F$2:$F$400,"dso_days",Meta!$D$2:$D$400,G$3,Meta!$A$2:$A$400,"GROUP")
A23: 应付账期（天） | C23: =SUMIFS(Meta!$G$2:$G$400,Meta!$F$2:$F$400,"dpo_days",Meta!$D$2:$D$400,C$3,Meta!$A$2:$A$400,"GROUP") | D23: =SUMIFS(Meta!$G$2:$G$400,Meta!$F$2:$F$400,"dpo_days",Meta!$D$2:$D$400,D$3,Meta!$A$2:$A$400,"GROUP") | E23: =SUMIFS(Meta!$G$2:$G$400,Meta!$F$2:$F$400,"dpo_days",Meta!$D$2:$D$400,E$3,Meta!$A$2:$A$400,"GROUP") | F23: =SUMIFS(Meta!$G$2:$G$400,Meta!$F$2:$F$400,"dpo_days",Meta!$D$2:$D$400,F$3,Meta!$A$2:$A$400,"GROUP") | G23: =SUMIFS(Meta!$G$2:$G$400,Meta!$F$2:$F$400,"dpo_days",Meta!$D$2:$D$400,G$3,Meta!$A$2:$A$400,"GROUP")
A24: 储值/递延率 | C24: =SUMIFS(Meta!$G$2:$G$400,Meta!$F$2:$F$400,"deferred_rate",Meta!$D$2:$D$400,C$3,Meta!$A$2:$A$400,"GROUP") | D24: =SUMIFS(Meta!$G$2:$G$400,Meta!$F$2:$F$400,"deferred_rate",Meta!$D$2:$D$400,D$3,Meta!$A$2:$A$400,"GROUP") | E24: =SUMIFS(Meta!$G$2:$G$400,Meta!$F$2:$F$400,"deferred_rate",Meta!$D$2:$D$400,E$3,Meta!$A$2:$A$400,"GROUP") | F24: =SUMIFS(Meta!$G$2:$G$400,Meta!$F$2:$F$400,"deferred_rate",Meta!$D$2:$D$400,F$3,Meta!$A$2:$A$400,"GROUP") | G24: =SUMIFS(Meta!$G$2:$G$400,Meta!$F$2:$F$400,"deferred_rate",Meta!$D$2:$D$400,G$3,Meta!$A$2:$A$400,"GROUP")
A25: 当年注资 | C25: =SUMIFS(Meta!$G$2:$G$400,Meta!$F$2:$F$400,"equity_inject",Meta!$D$2:$D$400,C$3,Meta!$A$2:$A$400,"GROUP") | D25: =SUMIFS(Meta!$G$2:$G$400,Meta!$F$2:$F$400,"equity_inject",Meta!$D$2:$D$400,D$3,Meta!$A$2:$A$400,"GROUP") | E25: =SUMIFS(Meta!$G$2:$G$400,Meta!$F$2:$F$400,"equity_inject",Meta!$D$2:$D$400,E$3,Meta!$A$2:$A$400,"GROUP") | F25: =SUMIFS(Meta!$G$2:$G$400,Meta!$F$2:$F$400,"equity_inject",Meta!$D$2:$D$400,F$3,Meta!$A$2:$A$400,"GROUP") | G25: =SUMIFS(Meta!$G$2:$G$400,Meta!$F$2:$F$400,"equity_inject",Meta!$D$2:$D$400,G$3,Meta!$A$2:$A$400,"GROUP")
A26: 期初实收资本 | C26: =SUMIFS(Meta!$G$2:$G$400,Meta!$F$2:$F$400,"open_pi",Meta!$D$2:$D$400,C$3,Meta!$A$2:$A$400,"GROUP") | D26: =SUMIFS(Meta!$G$2:$G$400,Meta!$F$2:$F$400,"open_pi",Meta!$D$2:$D$400,D$3,Meta!$A$2:$A$400,"GROUP") | E26: =SUMIFS(Meta!$G$2:$G$400,Meta!$F$2:$F$400,"open_pi",Meta!$D$2:$D$400,E$3,Meta!$A$2:$A$400,"GROUP") | F26: =SUMIFS(Meta!$G$2:$G$400,Meta!$F$2:$F$400,"open_pi",Meta!$D$2:$D$400,F$3,Meta!$A$2:$A$400,"GROUP") | G26: =SUMIFS(Meta!$G$2:$G$400,Meta!$F$2:$F$400,"open_pi",Meta!$D$2:$D$400,G$3,Meta!$A$2:$A$400,"GROUP")
A27: 期初未分配利润 | C27: =SUMIFS(Meta!$G$2:$G$400,Meta!$F$2:$F$400,"open_re",Meta!$D$2:$D$400,C$3,Meta!$A$2:$A$400,"GROUP") | D27: =SUMIFS(Meta!$G$2:$G$400,Meta!$F$2:$F$400,"open_re",Meta!$D$2:$D$400,D$3,Meta!$A$2:$A$400,"GROUP") | E27: =SUMIFS(Meta!$G$2:$G$400,Meta!$F$2:$F$400,"open_re",Meta!$D$2:$D$400,E$3,Meta!$A$2:$A$400,"GROUP") | F27: =SUMIFS(Meta!$G$2:$G$400,Meta!$F$2:$F$400,"open_re",Meta!$D$2:$D$400,F$3,Meta!$A$2:$A$400,"GROUP") | G27: =SUMIFS(Meta!$G$2:$G$400,Meta!$F$2:$F$400,"open_re",Meta!$D$2:$D$400,G$3,Meta!$A$2:$A$400,"GROUP")
A28: 期初门店资产原值 | C28: =SUMIFS(Meta!$G$2:$G$400,Meta!$F$2:$F$400,"open_store_fa",Meta!$D$2:$D$400,C$3,Meta!$A$2:$A$400,"GROUP") | D28: =SUMIFS(Meta!$G$2:$G$400,Meta!$F$2:$F$400,"open_store_fa",Meta!$D$2:$D$400,D$3,Meta!$A$2:$A$400,"GROUP") | E28: =SUMIFS(Meta!$G$2:$G$400,Meta!$F$2:$F$400,"open_store_fa",Meta!$D$2:$D$400,E$3,Meta!$A$2:$A$400,"GROUP") | F28: =SUMIFS(Meta!$G$2:$G$400,Meta!$F$2:$F$400,"open_store_fa",Meta!$D$2:$D$400,F$3,Meta!$A$2:$A$400,"GROUP") | G28: =SUMIFS(Meta!$G$2:$G$400,Meta!$F$2:$F$400,"open_store_fa",Meta!$D$2:$D$400,G$3,Meta!$A$2:$A$400,"GROUP")
A29: ── 收入地区拆分 ──
A30: 一线 占比 | C30: =SUMIFS(Meta!$G$2:$G$400,Meta!$F$2:$F$400,"region_mix",Meta!$D$2:$D$400,C$3,Meta!$A$2:$A$400,"GROUP",Meta!$C$2:$C$400,"一线") | D30: =SUMIFS(Meta!$G$2:$G$400,Meta!$F$2:$F$400,"region_mix",Meta!$D$2:$D$400,D$3,Meta!$A$2:$A$400,"GROUP",Meta!$C$2:$C$400,"一线") | E30: =SUMIFS(Meta!$G$2:$G$400,Meta!$F$2:$F$400,"region_mix",Meta!$D$2:$D$400,E$3,Meta!$A$2:$A$400,"GROUP",Meta!$C$2:$C$400,"一线") | F30: =SUMIFS(Meta!$G$2:$G$400,Meta!$F$2:$F$400,"region_mix",Meta!$D$2:$D$400,F$3,Meta!$A$2:$A$400,"GROUP",Meta!$C$2:$C$400,"一线") | G30: =SUMIFS(Meta!$G$2:$G$400,Meta!$F$2:$F$400,"region_mix",Meta!$D$2:$D$400,G$3,Meta!$A$2:$A$400,"GROUP",Meta!$C$2:$C$400,"一线")
A31: 新一线 占比 | C31: =SUMIFS(Meta!$G$2:$G$400,Meta!$F$2:$F$400,"region_mix",Meta!$D$2:$D$400,C$3,Meta!$A$2:$A$400,"GROUP",Meta!$C$2:$C$400,"新一线") | D31: =SUMIFS(Meta!$G$2:$G$400,Meta!$F$2:$F$400,"region_mix",Meta!$D$2:$D$400,D$3,Meta!$A$2:$A$400,"GROUP",Meta!$C$2:$C$400,"新一线") | E31: =SUMIFS(Meta!$G$2:$G$400,Meta!$F$2:$F$400,"region_mix",Meta!$D$2:$D$400,E$3,Meta!$A$2:$A$400,"GROUP",Meta!$C$2:$C$400,"新一线") | F31: =SUMIFS(Meta!$G$2:$G$400,Meta!$F$2:$F$400,"region_mix",Meta!$D$2:$D$400,F$3,Meta!$A$2:$A$400,"GROUP",Meta!$C$2:$C$400,"新一线") | G31: =SUMIFS(Meta!$G$2:$G$400,Meta!$F$2:$F$400,"region_mix",Meta!$D$2:$D$400,G$3,Meta!$A$2:$A$400,"GROUP",Meta!$C$2:$C$400,"新一线")
A32: 二线及以下 占比 | C32: =SUMIFS(Meta!$G$2:$G$400,Meta!$F$2:$F$400,"region_mix",Meta!$D$2:$D$400,C$3,Meta!$A$2:$A$400,"GROUP",Meta!$C$2:$C$400,"二线及以下") | D32: =SUMIFS(Meta!$G$2:$G$400,Meta!$F$2:$F$400,"region_mix",Meta!$D$2:$D$400,D$3,Meta!$A$2:$A$400,"GROUP",Meta!$C$2:$C$400,"二线及以下") | E32: =SUMIFS(Meta!$G$2:$G$400,Meta!$F$2:$F$400,"region_mix",Meta!$D$2:$D$400,E$3,Meta!$A$2:$A$400,"GROUP",Meta!$C$2:$C$400,"二线及以下") | F32: =SUMIFS(Meta!$G$2:$G$400,Meta!$F$2:$F$400,"region_mix",Meta!$D$2:$D$400,F$3,Meta!$A$2:$A$400,"GROUP",Meta!$C$2:$C$400,"二线及以下") | G32: =SUMIFS(Meta!$G$2:$G$400,Meta!$F$2:$F$400,"region_mix",Meta!$D$2:$D$400,G$3,Meta!$A$2:$A$400,"GROUP",Meta!$C$2:$C$400,"二线及以下")
A33: 海外 占比 | C33: =SUMIFS(Meta!$G$2:$G$400,Meta!$F$2:$F$400,"region_mix",Meta!$D$2:$D$400,C$3,Meta!$A$2:$A$400,"GROUP",Meta!$C$2:$C$400,"海外") | D33: =SUMIFS(Meta!$G$2:$G$400,Meta!$F$2:$F$400,"region_mix",Meta!$D$2:$D$400,D$3,Meta!$A$2:$A$400,"GROUP",Meta!$C$2:$C$400,"海外") | E33: =SUMIFS(Meta!$G$2:$G$400,Meta!$F$2:$F$400,"region_mix",Meta!$D$2:$D$400,E$3,Meta!$A$2:$A$400,"GROUP",Meta!$C$2:$C$400,"海外") | F33: =SUMIFS(Meta!$G$2:$G$400,Meta!$F$2:$F$400,"region_mix",Meta!$D$2:$D$400,F$3,Meta!$A$2:$A$400,"GROUP",Meta!$C$2:$C$400,"海外") | G33: =SUMIFS(Meta!$G$2:$G$400,Meta!$F$2:$F$400,"region_mix",Meta!$D$2:$D$400,G$3,Meta!$A$2:$A$400,"GROUP",Meta!$C$2:$C$400,"海外")

Sheet StoreCapex
A1: 门店资产 · 批次折旧引擎
A2: 净增门店×单店投入，5 年直线 | 连锁扩张的资产负债表灵魂
A3: 科目（万元） | B3: 备注 | C3: 2023 | D3: 2024 | E3: 2025 | F3: 2026 | G3: 2027
A4: ── 批次明细（B=购置年，H=批次原值[取自Meta]）──
A5: 2023批 | B5: 2023 | C5: =IF(AND(C$3>=$B5,C$3<$B5+5),$H5/5,0) | D5: =IF(AND(D$3>=$B5,D$3<$B5+5),$H5/5,0) | E5: =IF(AND(E$3>=$B5,E$3<$B5+5),$H5/5,0) | F5: =IF(AND(F$3>=$B5,F$3<$B5+5),$H5/5,0) | G5: =IF(AND(G$3>=$B5,G$3<$B5+5),$H5/5,0) | H5: =SUMIFS(Meta!$G$2:$G$400,Meta!$F$2:$F$400,"open_store_fa",Meta!$D$2:$D$400,C$3,Meta!$A$2:$A$400,"GROUP")+(SUMIFS(Meta!$G$2:$G$400,Meta!$F$2:$F$400,"stores",Meta!$D$2:$D$400,C$3,Meta!$A$2:$A$400,"GROUP")-(SUMIFS(Meta!$G$2:$G$400,Meta!$F$2:$F$400,"open_store_fa",Meta!$D$2:$D$400,C$3,Meta!$A$2:$A$400,"GROUP")/SUMIFS(Meta!$G$2:$G$400,Meta!$F$2:$F$400,"capex_per_store",Meta!$D$2:$D$400,C$3,Meta!$A$2:$A$400,"GROUP")))*SUMIFS(Meta!$G$2:$G$400,Meta!$F$2:$F$400,"capex_per_store",Meta!$D$2:$D$400,C$3,Meta!$A$2:$A$400,"GROUP")
A6: 2024批 | B6: 2024 | C6: =IF(AND(C$3>=$B6,C$3<$B6+5),$H6/5,0) | D6: =IF(AND(D$3>=$B6,D$3<$B6+5),$H6/5,0) | E6: =IF(AND(E$3>=$B6,E$3<$B6+5),$H6/5,0) | F6: =IF(AND(F$3>=$B6,F$3<$B6+5),$H6/5,0) | G6: =IF(AND(G$3>=$B6,G$3<$B6+5),$H6/5,0) | H6: =(SUMIFS(Meta!$G$2:$G$400,Meta!$F$2:$F$400,"stores",Meta!$D$2:$D$400,D$3,Meta!$A$2:$A$400,"GROUP")-SUMIFS(Meta!$G$2:$G$400,Meta!$F$2:$F$400,"stores",Meta!$D$2:$D$400,C$3,Meta!$A$2:$A$400,"GROUP"))*SUMIFS(Meta!$G$2:$G$400,Meta!$F$2:$F$400,"capex_per_store",Meta!$D$2:$D$400,D$3,Meta!$A$2:$A$400,"GROUP")
A7: 2025批 | B7: 2025 | C7: =IF(AND(C$3>=$B7,C$3<$B7+5),$H7/5,0) | D7: =IF(AND(D$3>=$B7,D$3<$B7+5),$H7/5,0) | E7: =IF(AND(E$3>=$B7,E$3<$B7+5),$H7/5,0) | F7: =IF(AND(F$3>=$B7,F$3<$B7+5),$H7/5,0) | G7: =IF(AND(G$3>=$B7,G$3<$B7+5),$H7/5,0) | H7: =(SUMIFS(Meta!$G$2:$G$400,Meta!$F$2:$F$400,"stores",Meta!$D$2:$D$400,E$3,Meta!$A$2:$A$400,"GROUP")-SUMIFS(Meta!$G$2:$G$400,Meta!$F$2:$F$400,"stores",Meta!$D$2:$D$400,D$3,Meta!$A$2:$A$400,"GROUP"))*SUMIFS(Meta!$G$2:$G$400,Meta!$F$2:$F$400,"capex_per_store",Meta!$D$2:$D$400,E$3,Meta!$A$2:$A$400,"GROUP")
A8: 2026批 | B8: 2026 | C8: =IF(AND(C$3>=$B8,C$3<$B8+5),$H8/5,0) | D8: =IF(AND(D$3>=$B8,D$3<$B8+5),$H8/5,0) | E8: =IF(AND(E$3>=$B8,E$3<$B8+5),$H8/5,0) | F8: =IF(AND(F$3>=$B8,F$3<$B8+5),$H8/5,0) | G8: =IF(AND(G$3>=$B8,G$3<$B8+5),$H8/5,0) | H8: =(SUMIFS(Meta!$G$2:$G$400,Meta!$F$2:$F$400,"stores",Meta!$D$2:$D$400,F$3,Meta!$A$2:$A$400,"GROUP")-SUMIFS(Meta!$G$2:$G$400,Meta!$F$2:$F$400,"stores",Meta!$D$2:$D$400,E$3,Meta!$A$2:$A$400,"GROUP"))*SUMIFS(Meta!$G$2:$G$400,Meta!$F$2:$F$400,"capex_per_store",Meta!$D$2:$D$400,F$3,Meta!$A$2:$A$400,"GROUP")
A9: 2027批 | B9: 2027 | C9: =IF(AND(C$3>=$B9,C$3<$B9+5),$H9/5,0) | D9: =IF(AND(D$3>=$B9,D$3<$B9+5),$H9/5,0) | E9: =IF(AND(E$3>=$B9,E$3<$B9+5),$H9/5,0) | F9: =IF(AND(F$3>=$B9,F$3<$B9+5),$H9/5,0) | G9: =IF(AND(G$3>=$B9,G$3<$B9+5),$H9/5,0) | H9: =(SUMIFS(Meta!$G$2:$G$400,Meta!$F$2:$F$400,"stores",Meta!$D$2:$D$400,G$3,Meta!$A$2:$A$400,"GROUP")-SUMIFS(Meta!$G$2:$G$400,Meta!$F$2:$F$400,"stores",Meta!$D$2:$D$400,F$3,Meta!$A$2:$A$400,"GROUP"))*SUMIFS(Meta!$G$2:$G$400,Meta!$F$2:$F$400,"capex_per_store",Meta!$D$2:$D$400,G$3,Meta!$A$2:$A$400,"GROUP")
A11: 当年折旧 → COGS | B11: 门店折旧计入营业成本 | C11: =SUM(C5:C9) | D11: =SUM(D5:D9) | E11: =SUM(E5:E9) | F11: =SUM(F5:F9) | G11: =SUM(G5:G9)
A12: 门店资产净值 → BS | C12: =SUMIFS($H$5:$H$9,$B$5:$B$9,"<="&C$3)-SUM($C$11:C11) | D12: =SUMIFS($H$5:$H$9,$B$5:$B$9,"<="&D$3)-SUM($C$11:D11) | E12: =SUMIFS($H$5:$H$9,$B$5:$B$9,"<="&E$3)-SUM($C$11:E11) | F12: =SUMIFS($H$5:$H$9,$B$5:$B$9,"<="&F$3)-SUM($C$11:F11) | G12: =SUMIFS($H$5:$H$9,$B$5:$B$9,"<="&G$3)-SUM($C$11:G11)
A13: 当年门店 capex → CF | B13: 2023 扣期初存量=净增 | C13: =$H5-SUMIFS(Meta!$G$2:$G$400,Meta!$F$2:$F$400,"open_store_fa",Meta!$D$2:$D$400,C$3,Meta!$A$2:$A$400,"GROUP") | D13: =$H6 | E13: =$H7 | F13: =$H8 | G13: =$H9

Sheet IS
A1: 山雾咖啡 · 利润表
A2: 量×价：门店×杯量×客单 | 万元
A3: 科目（万元） | B3: 备注 | C3: 2023 | D3: 2024 | E3: 2025 | F3: 2026 | G3: 2027
A4: 收入 · 现制饮品 | B4: 门店×杯量×客单×365 | C4: =Assumptions!C5*Assumptions!C6*Assumptions!C7*365/10000 | D4: =Assumptions!D5*Assumptions!D6*Assumptions!D7*365/10000 | E4: =Assumptions!E5*Assumptions!E6*Assumptions!E7*365/10000 | F4: =Assumptions!F5*Assumptions!F6*Assumptions!F7*365/10000 | G4: =Assumptions!G5*Assumptions!G6*Assumptions!G7*365/10000
A5: 收入 · 零售产品 | C5: =IS!C4*Assumptions!C8 | D5: =IS!D4*Assumptions!D8 | E5: =IS!E4*Assumptions!E8 | F5: =IS!F4*Assumptions!F8 | G5: =IS!G4*Assumptions!G8
A6: 营业收入合计 | C6: =IS!C4+IS!C5 | D6: =IS!D4+IS!D5 | E6: =IS!E4+IS!E5 | F6: =IS!F4+IS!F5 | G6: =IS!G4+IS!G5
A7: 成本 · 原料 | C7: =IS!C6*Assumptions!C10 | D7: =IS!D6*Assumptions!D10 | E7: =IS!E6*Assumptions!E10 | F7: =IS!F6*Assumptions!F10 | G7: =IS!G6*Assumptions!G10
A8: 成本 · 门店运营 | B8: 租金+人工+水电 | C8: =Assumptions!C5*Assumptions!C11*12 | D8: =Assumptions!D5*Assumptions!D11*12 | E8: =Assumptions!E5*Assumptions!E11*12 | F8: =Assumptions!F5*Assumptions!F11*12 | G8: =Assumptions!G5*Assumptions!G11*12
A9: 成本 · 门店折旧 | C9: =StoreCapex!C11 | D9: =StoreCapex!D11 | E9: =StoreCapex!E11 | F9: =StoreCapex!F11 | G9: =StoreCapex!G11
A10: 营业成本合计 | C10: =SUM(IS!C7,IS!C8,IS!C9) | D10: =SUM(IS!D7,IS!D8,IS!D9) | E10: =SUM(IS!E7,IS!E8,IS!E9) | F10: =SUM(IS!F7,IS!F8,IS!F9) | G10: =SUM(IS!G7,IS!G8,IS!G9)
A11: 毛利润 | C11: =IS!C6-IS!C10 | D11: =IS!D6-IS!D10 | E11: =IS!E6-IS!E10 | F11: =IS!F6-IS!F10 | G11: =IS!G6-IS!G10
A12: 营销费用 | B12: 补贴退坡 | C12: =IS!C6*Assumptions!C12 | D12: =IS!D6*Assumptions!D12 | E12: =IS!E6*Assumptions!E12 | F12: =IS!F6*Assumptions!F12 | G12: =IS!G6*Assumptions!G12
A13: 研发费用（数字化） | C13: =Assumptions!C14*Assumptions!C17 | D13: =Assumptions!D14*Assumptions!D17 | E13: =Assumptions!E14*Assumptions!E17 | F13: =Assumptions!F14*Assumptions!F17 | G13: =Assumptions!G14*Assumptions!G17
A14: 销售费用（总部） | C14: =Assumptions!C15*Assumptions!C18 | D14: =Assumptions!D15*Assumptions!D18 | E14: =Assumptions!E15*Assumptions!E18 | F14: =Assumptions!F15*Assumptions!F18 | G14: =Assumptions!G15*Assumptions!G18
A15: 管理费用 | C15: =Assumptions!C16*Assumptions!C19 | D15: =Assumptions!D16*Assumptions!D19 | E15: =Assumptions!E16*Assumptions!E19 | F15: =Assumptions!F16*Assumptions!F19 | G15: =Assumptions!G16*Assumptions!G19
A16: EBIT | C16: =IS!C11-IS!C12-IS!C13-IS!C14-IS!C15 | D16: =IS!D11-IS!D12-IS!D13-IS!D14-IS!D15 | E16: =IS!E11-IS!E12-IS!E13-IS!E14-IS!E15 | F16: =IS!F11-IS!F12-IS!F13-IS!F14-IS!F15 | G16: =IS!G11-IS!G12-IS!G13-IS!G14-IS!G15
A17: 所得税 | C17: =MAX(0,IS!C16)*Assumptions!C21 | D17: =MAX(0,IS!D16)*Assumptions!D21 | E17: =MAX(0,IS!E16)*Assumptions!E21 | F17: =MAX(0,IS!F16)*Assumptions!F21 | G17: =MAX(0,IS!G16)*Assumptions!G21
A18: 净利润 | C18: =IS!C16-IS!C17 | D18: =IS!D16-IS!D17 | E18: =IS!E16-IS!E17 | F18: =IS!F16-IS!F17 | G18: =IS!G16-IS!G17

Sheet BS
A1: 山雾咖啡 · 资产负债表
A2: 现金=倒挤项 → 结构性平衡 | 万元
A3: 科目（万元） | B3: 备注 | C3: 2023 | D3: 2024 | E3: 2025 | F3: 2026 | G3: 2027
A4: 应收账款 | B4: C端占比高，账期短 | C4: =IS!C6*Assumptions!C22/365 | D4: =IS!D6*Assumptions!D22/365 | E4: =IS!E6*Assumptions!E22/365 | F4: =IS!F6*Assumptions!F22/365 | G4: =IS!G6*Assumptions!G22/365
A5: 门店资产净值 | C5: =StoreCapex!C12 | D5: =StoreCapex!D12 | E5: =StoreCapex!E12 | F5: =StoreCapex!F12 | G5: =StoreCapex!G12
A6: 非现金资产合计 | C6: =BS!C4+BS!C5 | D6: =BS!D4+BS!D5 | E6: =BS!E4+BS!E5 | F6: =BS!F4+BS!F5 | G6: =BS!G4+BS!G5
A7: 应付账款 | C7: =(IS!C10+IS!C12+IS!C13+IS!C14+IS!C15-StoreCapex!C11)*Assumptions!C23/365 | D7: =(IS!D10+IS!D12+IS!D13+IS!D14+IS!D15-StoreCapex!D11)*Assumptions!D23/365 | E7: =(IS!E10+IS!E12+IS!E13+IS!E14+IS!E15-StoreCapex!E11)*Assumptions!E23/365 | F7: =(IS!F10+IS!F12+IS!F13+IS!F14+IS!F15-StoreCapex!F11)*Assumptions!F23/365 | G7: =(IS!G10+IS!G12+IS!G13+IS!G14+IS!G15-StoreCapex!G11)*Assumptions!G23/365
A8: 递延收益（储值卡） | C8: =IS!C6*Assumptions!C24 | D8: =IS!D6*Assumptions!D24 | E8: =IS!E6*Assumptions!E24 | F8: =IS!F6*Assumptions!F24 | G8: =IS!G6*Assumptions!G24
A9: 负债合计 | C9: =BS!C7+BS!C8 | D9: =BS!D7+BS!D8 | E9: =BS!E7+BS!E8 | F9: =BS!F7+BS!F8 | G9: =BS!G7+BS!G8
A10: 实收资本 | C10: =Assumptions!C26+Assumptions!C25 | D10: =C10+Assumptions!D25 | E10: =D10+Assumptions!E25 | F10: =E10+Assumptions!F25 | G10: =F10+Assumptions!G25
A11: 未分配利润 | C11: =Assumptions!C27+IS!C18 | D11: =C11+IS!D18 | E11: =D11+IS!E18 | F11: =E11+IS!F18 | G11: =F11+IS!G18
A12: 货币资金（倒挤） | C12: =BS!C9+BS!C10+BS!C11-BS!C6 | D12: =BS!D9+BS!D10+BS!D11-BS!D6 | E12: =BS!E9+BS!E10+BS!E11-BS!E6 | F12: =BS!F9+BS!F10+BS!F11-BS!F6 | G12: =BS!G9+BS!G10+BS!G11-BS!G6
A13: 资产总计 | C13: =BS!C12+BS!C6 | D13: =BS!D12+BS!D6 | E13: =BS!E12+BS!E6 | F13: =BS!F12+BS!F6 | G13: =BS!G12+BS!G6
A14: 负债+权益合计 | C14: =BS!C9+BS!C10+BS!C11 | D14: =BS!D9+BS!D10+BS!D11 | E14: =BS!E9+BS!E10+BS!E11 | F14: =BS!F9+BS!F10+BS!F11 | G14: =BS!G9+BS!G10+BS!G11
A15: ★ BS 平衡差（应全 0）
A16: 资产 − 负债 − 权益 | C16: =BS!C13-BS!C14 | D16: =BS!D13-BS!D14 | E16: =BS!E13-BS!E14 | F16: =BS!F13-BS!F14 | G16: =BS!G13-BS!G14

Sheet CF
A1: 山雾咖啡 · 现金流量表（间接法）
A2: 与 BS 倒挤现金互为勾稽 | 万元
A3: 科目（万元） | B3: 备注 | C3: 2023 | D3: 2024 | E3: 2025 | F3: 2026 | G3: 2027
A4: 净利润 | C4: =IS!C18 | D4: =IS!D18 | E4: =IS!E18 | F4: =IS!F18 | G4: =IS!G18
A5: 加：门店折旧 | C5: =StoreCapex!C11 | D5: =StoreCapex!D11 | E5: =StoreCapex!E11 | F5: =StoreCapex!F11 | G5: =StoreCapex!G11
A6: 减：应收增加 | C6: =-(BS!C4-(0)) | D6: =-(BS!D4-(BS!C4)) | E6: =-(BS!E4-(BS!D4)) | F6: =-(BS!F4-(BS!E4)) | G6: =-(BS!G4-(BS!F4))
A7: 加：递延增加 | C7: =BS!C8-(0) | D7: =BS!D8-(BS!C8) | E7: =BS!E8-(BS!D8) | F7: =BS!F8-(BS!E8) | G7: =BS!G8-(BS!F8)
A8: 加：应付增加 | C8: =BS!C7-(0) | D8: =BS!D7-(BS!C7) | E8: =BS!E7-(BS!D7) | F8: =BS!F7-(BS!E7) | G8: =BS!G7-(BS!F7)
A9: 经营现金流 | C9: =CF!C4+CF!C5+CF!C6+CF!C7+CF!C8 | D9: =CF!D4+CF!D5+CF!D6+CF!D7+CF!D8 | E9: =CF!E4+CF!E5+CF!E6+CF!E7+CF!E8 | F9: =CF!F4+CF!F5+CF!F6+CF!F7+CF!F8 | G9: =CF!G4+CF!G5+CF!G6+CF!G7+CF!G8
A10: 投资现金流（开店 capex） | C10: =-StoreCapex!C13 | D10: =-StoreCapex!D13 | E10: =-StoreCapex!E13 | F10: =-StoreCapex!F13 | G10: =-StoreCapex!G13
A11: 筹资：股权注资 | C11: =Assumptions!C25 | D11: =Assumptions!D25 | E11: =Assumptions!E25 | F11: =Assumptions!F25 | G11: =Assumptions!G25
A12: 现金净变动 | C12: =CF!C9+CF!C10+CF!C11 | D12: =CF!D9+CF!D10+CF!D11 | E12: =CF!E9+CF!E10+CF!E11 | F12: =CF!F9+CF!F10+CF!F11 | G12: =CF!G9+CF!G10+CF!G11
A13: 期末现金（CF） | C13: =64000.0+CF!C12 | D13: =C13+CF!D12 | E13: =D13+CF!E12 | F13: =E13+CF!F12 | G13: =F13+CF!G12
A14: 期末现金（BS 倒挤） | C14: =BS!C12 | D14: =BS!D12 | E14: =BS!E12 | F14: =BS!F12 | G14: =BS!G12
A15: ★ CF=BS 差异（应全 0）
A16: CF推导 − BS倒挤 | C16: =CF!C13-CF!C14 | D16: =CF!D13-CF!D14 | E16: =CF!E13-CF!E14 | F16: =CF!F13-CF!F14 | G16: =CF!G13-CF!G14

Sheet FactTable
A1: entity | B1: segment | C1: region | D1: period | E1: account | F1: value
A2: GROUP | B2: 现制饮品 | C2: 一线 | D2: 2023 | E2: 收入 | F2: 68985
A3: GROUP | B3: 现制饮品 | C3: 新一线 | D3: 2023 | E3: 收入 | F3: 45990
A4: GROUP | B4: 现制饮品 | C4: 二线及以下 | D4: 2023 | E4: 收入 | F4: 27594
A5: GROUP | B5: 现制饮品 | C5: 海外 | D5: 2023 | E5: 收入 | F5: 10731
A6: GROUP | B6: 现制饮品 | C6: 集团 | D6: 2023 | E6: 成本 | F6: 117700.11
A7: GROUP | B7: 零售产品 | C7: 一线 | D7: 2023 | E7: 收入 | F7: 5518.8
A8: GROUP | B8: 零售产品 | C8: 新一线 | D8: 2023 | E8: 收入 | F8: 3679.2
A9: GROUP | B9: 零售产品 | C9: 二线及以下 | D9: 2023 | E9: 收入 | F9: 2207.52
A10: GROUP | B10: 零售产品 | C10: 海外 | D10: 2023 | E10: 收入 | F10: 858.48
A11: GROUP | B11: 零售产品 | C11: 集团 | D11: 2023 | E11: 成本 | F11: 9416.0089
A12: GROUP | B12: 集团 | C12: 集团 | D12: 2023 | E12: 毛利 | F12: 38447.88
A13: GROUP | B13: 集团 | C13: 集团 | D13: 2023 | E13: EBIT | F13: 19399.94
... A66: GROUP | B66: 集团 | C66: 集团 | D66: 2027 | E66: 净利润 | F66: 223057.52

Sheet Dashboard
A1: 山雾咖啡 · 维度看板
A2: 黄格下拉：业务线 / 地区 / 期间（*=全部；期间列数字用 >0 匹配全部）
B4: 业务线 | C4: * | D4: 地区 | E4: * | F4: 期间 | G4: * | H4: =IF(G4="*",">0",G4)
A6: 营业收入 | B6: =SUMIFS(FactTable!$F$2:$F$66,FactTable!$E$2:$E$66,"收入",FactTable!$B$2:$B$66,$C$4,FactTable!$C$2:$C$66,$E$4,FactTable!$D$2:$D$66,$H$4) | C6: =SUMIFS(FactTable!$F$2:$F$66,FactTable!$E$2:$E$66,"收入",FactTable!$B$2:$B$66,$C$4,FactTable!$C$2:$C$66,$E$4,FactTable!$D$2:$D$66,$H$4) | D6: =SUMIFS(FactTable!$F$2:$F$66,FactTable!$E$2:$E$66,"收入",FactTable!$B$2:$B$66,$C$4,FactTable!$C$2:$C$66,$E$4,FactTable!$D$2:$D$66,$H$4) | E6: =SUMIFS(FactTable!$F$2:$F$66,FactTable!$E$2:$E$66,"收入",FactTable!$B$2:$B$66,$C$4,FactTable!$C$2:$C$66,$E$4,FactTable!$D$2:$D$66,$H$4) | F6: =SUMIFS(FactTable!$F$2:$F$66,FactTable!$E$2:$E$66,"收入",FactTable!$B$2:$B$66,$C$4,FactTable!$C$2:$C$66,$E$4,FactTable!$D$2:$D$66,$H$4)
A7: 营业成本 | B7: =SUMIFS(FactTable!$F$2:$F$66,FactTable!$E$2:$E$66,"成本",FactTable!$B$2:$B$66,$C$4,FactTable!$C$2:$C$66,$E$4,FactTable!$D$2:$D$66,$H$4) | C7: =SUMIFS(FactTable!$F$2:$F$66,FactTable!$E$2:$E$66,"成本",FactTable!$B$2:$B$66,$C$4,FactTable!$C$2:$C$66,$E$4,FactTable!$D$2:$D$66,$H$4) | D7: =SUMIFS(FactTable!$F$2:$F$66,FactTable!$E$2:$E$66,"成本",FactTable!$B$2:$B$66,$C$4,FactTable!$C$2:$C$66,$E$4,FactTable!$D$2:$D$66,$H$4) | E7: =SUMIFS(FactTable!$F$2:$F$66,FactTable!$E$2:$E$66,"成本",FactTable!$B$2:$B$66,$C$4,FactTable!$C$2:$C$66,$E$4,FactTable!$D$2:$D$66,$H$4) | F7: =SUMIFS(FactTable!$F$2:$F$66,FactTable!$E$2:$E$66,"成本",FactTable!$B$2:$B$66,$C$4,FactTable!$C$2:$C$66,$E$4,FactTable!$D$2:$D$66,$H$4)
A8: 毛利润 | B8: =SUMIFS(FactTable!$F$2:$F$66,FactTable!$E$2:$E$66,"毛利",FactTable!$B$2:$B$66,$C$4,FactTable!$C$2:$C$66,$E$4,FactTable!$D$2:$D$66,$H$4) | C8: =SUMIFS(FactTable!$F$2:$F$66,FactTable!$E$2:$E$66,"毛利",FactTable!$B$2:$B$66,$C$4,FactTable!$C$2:$C$66,$E$4,FactTable!$D$2:$D$66,$H$4) | D8: =SUMIFS(FactTable!$F$2:$F$66,FactTable!$E$2:$E$66,"毛利",FactTable!$B$2:$B$66,$C$4,FactTable!$C$2:$C$66,$E$4,FactTable!$D$2:$D$66,$H$4) | E8: =SUMIFS(FactTable!$F$2:$F$66,FactTable!$E$2:$E$66,"毛利",FactTable!$B$2:$B$66,$C$4,FactTable!$C$2:$C$66,$E$4,FactTable!$D$2:$D$66,$H$4) | F8: =SUMIFS(FactTable!$F$2:$F$66,FactTable!$E$2:$E$66,"毛利",FactTable!$B$2:$B$66,$C$4,FactTable!$C$2:$C$66,$E$4,FactTable!$D$2:$D$66,$H$4)
A9: EBIT | B9: =SUMIFS(FactTable!$F$2:$F$66,FactTable!$E$2:$E$66,"EBIT",FactTable!$B$2:$B$66,$C$4,FactTable!$C$2:$C$66,$E$4,FactTable!$D$2:$D$66,$H$4) | C9: =SUMIFS(FactTable!$F$2:$F$66,FactTable!$E$2:$E$66,"EBIT",FactTable!$B$2:$B$66,$C$4,FactTable!$C$2:$C$66,$E$4,FactTable!$D$2:$D$66,$H$4) | D9: =SUMIFS(FactTable!$F$2:$F$66,FactTable!$E$2:$E$66,"EBIT",FactTable!$B$2:$B$66,$C$4,FactTable!$C$2:$C$66,$E$4,FactTable!$D$2:$D$66,$H$4) | E9: =SUMIFS(FactTable!$F$2:$F$66,FactTable!$E$2:$E$66,"EBIT",FactTable!$B$2:$B$66,$C$4,FactTable!$C$2:$C$66,$E$4,FactTable!$D$2:$D$66,$H$4) | F9: =SUMIFS(FactTable!$F$2:$F$66,FactTable!$E$2:$E$66,"EBIT",FactTable!$B$2:$B$66,$C$4,FactTable!$C$2:$C$66,$E$4,FactTable!$D$2:$D$66,$H$4)
A10: 净利润 | B10: =SUMIFS(FactTable!$F$2:$F$66,FactTable!$E$2:$E$66,"净利润",FactTable!$B$2:$B$66,$C$4,FactTable!$C$2:$C$66,$E$4,FactTable!$D$2:$D$66,$H$4) | C10: =SUMIFS(FactTable!$F$2:$F$66,FactTable!$E$2:$E$66,"净利润",FactTable!$B$2:$B$66,$C$4,FactTable!$C$2:$C$66,$E$4,FactTable!$D$2:$D$66,$H$4) | D10: =SUMIFS(FactTable!$F$2:$F$66,FactTable!$E$2:$E$66,"净利润",FactTable!$B$2:$B$66,$C$4,FactTable!$C$2:$C$66,$E$4,FactTable!$D$2:$D$66,$H$4) | E10: =SUMIFS(FactTable!$F$2:$F$66,FactTable!$E$2:$E$66,"净利润",FactTable!$B$2:$B$66,$C$4,FactTable!$C$2:$C$66,$E$4,FactTable!$D$2:$D$66,$H$4) | F10: =SUMIFS(FactTable!$F$2:$F$66,FactTable!$E$2:$E$66,"净利润",FactTable!$B$2:$B$66,$C$4,FactTable!$C$2:$C$66,$E$4,FactTable!$D$2:$D$66,$H$4)
A11: 毛利率 | B11: =IF(B6=0,0,B8/B6) | C11: =IF(C6=0,0,C8/C6) | D11: =IF(D6=0,0,D8/D6) | E11: =IF(E6=0,0,E8/E6) | F11: =IF(F6=0,0,F8/F6)
A13: ★ 反查：SUMIFS全量 vs IS 收入
B14: =SUMIFS(FactTable!$F$2:$F$66,FactTable!$E$2:$E$66,"收入",FactTable!$D$2:$D$66,2023)-IS!C6 | C14: =SUMIFS(FactTable!$F$2:$F$66,FactTable!$E$2:$E$66,"收入",FactTable!$D$2:$D$66,2024)-IS!D6 | D14: =SUMIFS(FactTable!$F$2:$F$66,FactTable!$E$2:$E$66,"收入",FactTable!$D$2:$D$66,2025)-IS!E6 | E14: =SUMIFS(FactTable!$F$2:$F$66,FactTable!$E$2:$E$66,"收入",FactTable!$D$2:$D$66,2026)-IS!F6 | F14: =SUMIFS(FactTable!$F$2:$F$66,FactTable!$E$2:$E$66,"收入",FactTable!$D$2:$D$66,2027)-IS!G6

Sheet UE
A1: 单位经济 · 单店模型
A2: volume_price 模式的 UE = 单店 unit economics | 万元
A3: 科目（万元） | B3: 备注 | C3: 2023 | D3: 2024 | E3: 2025 | F3: 2026 | G3: 2027
A4: 单店年收入 | C4: =IS!C6/Assumptions!C5 | D4: =IS!D6/Assumptions!D5 | E4: =IS!E6/Assumptions!E5 | F4: =IS!F6/Assumptions!F5 | G4: =IS!G6/Assumptions!G5
A5: 单店年毛利 | B5: 扣除原料+门店运营（未扣折旧） | C5: =(IS!C6-IS!C8-IS!C7)/Assumptions!C5 | D5: =(IS!D6-IS!D8-IS!D7)/Assumptions!D5 | E5: =(IS!E6-IS!E8-IS!E7)/Assumptions!E5 | F5: =(IS!F6-IS!F8-IS!F7)/Assumptions!F5 | G5: =(IS!G6-IS!G8-IS!G7)/Assumptions!G5
A6: 单店回本期（月） | B6: 投入45万 ÷ 月毛利 | C6: =Assumptions!C20/(UE!C5/12) | D6: =Assumptions!D20/(UE!D5/12) | E6: =Assumptions!E20/(UE!E5/12) | F6: =Assumptions!F20/(UE!F5/12) | G6: =Assumptions!G20/(UE!G5/12)
A7: 同店增速（收入/店） | B7: 量价拆分的增长质量 | C7: =0 | D7: =UE!D4/UE!C4-1 | E7: =UE!E4/UE!D4-1 | F7: =UE!F4/UE!E4-1 | G7: =UE!G4/UE!F4-1

Sheet Checks
A1: 勾稽自检面板
A2: 全公式实时链接 | 红灯即不可交付
A3: 科目（万元） | B3: 备注 | C3: 2023 | D3: 2024 | E3: 2025 | F3: 2026 | G3: 2027
A4: C1 BS 平衡（资产−负债−权益） | C4: =BS!C16 | D4: =BS!D16 | E4: =BS!E16 | F4: =BS!F16 | G4: =BS!G16 | I4: =IF(AND(ABS(C4)<0.01,ABS(D4)<0.01,ABS(E4)<0.01,ABS(F4)<0.01,ABS(G4)<0.01),"✅ PASS","❌ FAIL")
A5: C2 CF=BS 现金 | C5: =CF!C16 | D5: =CF!D16 | E5: =CF!E16 | F5: =CF!F16 | G5: =CF!G16 | I5: =IF(AND(ABS(C5)<0.01,ABS(D5)<0.01,ABS(E5)<0.01,ABS(F5)<0.01,ABS(G5)<0.01),"✅ PASS","❌ FAIL")
A6: C3 FactTable 反查 vs IS 收入 | B6: SUMIFS 全量 = IS 公式值 | C6: =SUMIFS(FactTable!$F$2:$F$66,FactTable!$E$2:$E$66,"收入",FactTable!$D$2:$D$66,2023)-IS!C6 | D6: =SUMIFS(FactTable!$F$2:$F$66,FactTable!$E$2:$E$66,"收入",FactTable!$D$2:$D$66,2024)-IS!D6 | E6: =SUMIFS(FactTable!$F$2:$F$66,FactTable!$E$2:$E$66,"收入",FactTable!$D$2:$D$66,2025)-IS!E6 | F6: =SUMIFS(FactTable!$F$2:$F$66,FactTable!$E$2:$E$66,"收入",FactTable!$D$2:$D$66,2026)-IS!F6 | G6: =SUMIFS(FactTable!$F$2:$F$66,FactTable!$E$2:$E$66,"收入",FactTable!$D$2:$D$66,2027)-IS!G6 | I6: =IF(AND(ABS(C6)<0.01,ABS(D6)<0.01,ABS(E6)<0.01,ABS(F6)<0.01,ABS(G6)<0.01),"✅ PASS","❌ FAIL")
A7: C4 RE 滚动 | C7: =BS!C11-20000.0-IS!C18 | D7: =BS!D11-BS!C11-IS!D18 | E7: =BS!E11-BS!D11-IS!E18 | F7: =BS!F11-BS!E11-IS!F18 | G7: =BS!G11-BS!F11-IS!G18 | I7: =IF(AND(ABS(C7)<0.01,ABS(D7)<0.01,ABS(E7)<0.01,ABS(F7)<0.01,ABS(G7)<0.01),"✅ PASS","❌ FAIL")
A9: 总检灯 | C9: =IF(COUNTIF(I4:I7,"✅ PASS")=4,"🟢 全部通过","🔴 存在失败")

Sheet Calibration
A1: 参数校准 · 真实数据源管道
A2: tsdata·A股连锁餐饮可比（广州酒家/同庆楼/全聚德/佳禾食品 2022-2023 年报）
A3: 科目（万元） | B3: 备注 | C3: 2023 | D3: 2024 | E3: 2025 | F3: 2026 | G3: 2027
A4: 参数 | B4: 原假设(先验) | C4: 真实区间 | D4: 校准值 | E4: 来源 | F4: 偏差解释
A5: 原料成本率 COGS_RATE | B5: 0.33→0.30 | C5: 可比毛利率 18-36%（中位18.2%） | D5: 0.33→0.305 | E5: tsdata·A股餐饮校准 | F5: 现制咖啡外带小店结构优于堂食可比，取区间上部
A6: 单店月运营 STORE_OPEX_M | B6: 6.8→7.4 万 | C6: 人工租金通胀（可比销售费用率中位4.3%） | D6: 6.8→8.0 万 | E6: tsdata·A股餐饮校准 | F6: 原假设通胀不足，上调
A7: 营销费率 MKT_RATE | B7: 9%→6% | C7: 可比销售费用率 2.8-10.7%（中位4.3%） | D7: 8.5%→5.2% | E7: tsdata·A股餐饮校准 | F7: 咖啡补贴期叙事保留上部，退坡加快
A8: 净利率（结果校验） | B8: 原模型2027E≈25% | C8: 可比净利率 4-13%（中位7.3%） | D8: 校准后≈22% | E8: 对照校验 | F8: 仍高于可比：直营咖啡单店模型差异，明示而非隐藏
A9: 门店数/杯量/客单 | B9: 先验假设 | C9: A股无纯咖啡可比（瑞幸在美/粉单） | D9: 保留先验 | E9: 低置信度假设 | F9: 降级链走到可比公司环，参数级差异大，如实标注
A11: 管道：tsdata.get_pro().income() → 年报口径毛利率/费用率 → 区间对照 → 参数修正 → Meta source 标注
