Workbook

Sheet Cover
A1: 智擎集团 · 集团财务分析模型
A2: 虚构大模型集团（参考智谱商业模式）| Python+openpyxl 全公式生成 | 单位：万元
A4: 导航 | B4: 说明
A5: Meta | B5: 数据层宽表——全模型唯一取数源，日常只改 G 列
A6: Assumptions | B6: 指标视图层——全部实时取自 Meta（SUMIFS）
A7: Capex_Dep | B7: GPU 资本开支与折旧引擎（批次法）
A8: Cloud_IS | B8: 智擎云 · MaaS（单体全量）
A9: Ind_IS | B9: 智擎行业 · 私有化+解决方案
A10: Toc_IS | B10: 智擎互联 · C端（母持 80%）
A11: HoldCo_IS | B11: 智擎研究院 · 全量三表（关联收入方）
A12: IC_Register | B12: 内部交易登记簿（T1/T2/T3）
A13: IC_Recon | B13: 关联方对账矩阵 + cut-off 在途调节
A14: Eliminations | B14: 合并抵消分录底稿（E0-E3）
A15: Consol_IS | B15: 合并三表（Σ单体−抵消）
... A19: Checks | B19: 勾稽自检面板：8 组断言全绿才可信
A21: 集团速览（合并口径） | B21: 2023 | C21: 2024 | D21: 2025 | E21: 2026 | F21: 2027
A22: 营业收入 | B22: =Consol_IS!C6 | C22: =Consol_IS!D6 | D22: =Consol_IS!E6 | E22: =Consol_IS!F6 | F22: =Consol_IS!G6
A23: 净利润 | B23: =Consol_IS!C16 | C23: =Consol_IS!D16 | D23: =Consol_IS!E16 | E23: =Consol_IS!F16 | F23: =Consol_IS!G16
A24: 归母净利润 | B24: =Consol_IS!C18 | C24: =Consol_IS!D18 | D24: =Consol_IS!E18 | E24: =Consol_IS!F18 | F24: =Consol_IS!G18
A25: 期末现金 | B25: =Consol_BS!C4 | C25: =Consol_BS!D4 | D25: =Consol_BS!E4 | E25: =Consol_BS!F4 | F25: =Consol_BS!G4
A26: GPU 净值 | B26: =Consol_BS!C6 | C26: =Consol_BS!D6 | D26: =Consol_BS!E6 | E26: =Consol_BS!F6 | F26: =Consol_BS!G6
A28: 勾稽总检灯 → | B28: =IF(Checks!C34="","",Checks!C34)

Sheet Meta
A1: Meta · 数据层宽表（全模型唯一取数源）
A2: 字段：主体/业务线/地区/期间/场景(A实际·B预算)/指标/值/来源/备注 | 日常=按期灌数与维护来源；引擎与公式零改动
A3: entity | B3: segment | C3: region | D3: period | E3: scenario | F3: metric | G3: value | H3: source | I3: note
A4: GROUP | D4: 2023 | E4: ACTUAL | F4: tax_rate | G4: 0.15 | H4: 假设初始化 | I4: 所得税率
A5: GROUP | D5: 2023 | E5: ACTUAL | F5: dso_days | G5: 60 | H5: 假设初始化 | I5: 应收账期（天）
A6: GROUP | D6: 2023 | E6: ACTUAL | F6: dpo_days | G6: 45 | H6: 假设初始化 | I6: 应付账期（天）
A7: GROUP | D7: 2023 | E7: ACTUAL | F7: ic_days | G7: 60 | H7: 假设初始化 | I7: 内部往来账期（天）
A8: GROUP | D8: 2023 | E8: ACTUAL | F8: wacc | G8: 0.1 | H8: 假设初始化 | I8: WACC
A9: GROUP | C9: 华东 | D9: 2023 | E9: ACTUAL | F9: region_mix | G9: 0.35 | H9: 行业研究 | I9: 收入地区占比
A10: GROUP | C10: 华北 | D10: 2023 | E10: ACTUAL | F10: region_mix | G10: 0.3 | H10: 行业研究 | I10: 收入地区占比
A11: GROUP | C11: 华南 | D11: 2023 | E11: ACTUAL | F11: region_mix | G11: 0.2 | H11: 行业研究 | I11: 收入地区占比
A12: GROUP | C12: 海外 | D12: 2023 | E12: ACTUAL | F12: region_mix | G12: 0.15 | H12: 行业研究 | I12: 收入地区占比
A13: CLOUD | D13: 2023 | E13: ACTUAL | F13: token_volume_day | G13: 30 | H13: 假设初始化 | I13: 日均 token 消耗（B/day）
A14: CLOUD | D14: 2023 | E14: ACTUAL | F14: api_price | G14: 5.5 | H14: 假设初始化 | I14: 综合单价（元/M tokens）
A15: CLOUD | D15: 2023 | E15: ACTUAL | F15: inference_ucost | G15: 2.5 | H15: 假设初始化 | I15: 推理单位成本（元/M tok）
A16: CLOUD | D16: 2023 | E16: ACTUAL | F16: bandwidth_fee | G16: 300 | H16: 假设初始化 | I16: 带宽机房费用（万）
A17: CLOUD | D17: 2023 | E17: ACTUAL | F17: customers | G17: 800 | H17: 假设初始化 | I17: 付费客户数（家）
A18: CLOUD | D18: 2023 | E18: ACTUAL | F18: churn_m | G18: 0.012 | H18: 假设初始化 | I18: 月流失率
A19: IND | D19: 2023 | E19: ACTUAL | F19: projects_pvt | G19: 8 | H19: 假设初始化 | I19: 私有化项目数（个）
A20: IND | D20: 2023 | E20: ACTUAL | F20: avg_contract | G20: 1000 | H20: 假设初始化 | I20: 平均合同额（万）
A21: IND | D21: 2023 | E21: ACTUAL | F21: subscribers_sol | G21: 12 | H21: 假设初始化 | I21: 解决方案签约客户（累计）
A22: IND | D22: 2023 | E22: ACTUAL | F22: sub_fee | G22: 100 | H22: 假设初始化 | I22: 解决方案年费（万）
A23: IND | D23: 2023 | E23: ACTUAL | F23: cogs_rate_pvt | G23: 0.61 | H23: 假设初始化 | I23: 私有化成本率
A24: IND | D24: 2023 | E24: ACTUAL | F24: cogs_rate_sol | G24: 0.42 | H24: 假设初始化 | I24: 解决方案成本率
... A86: GROUP | D86: 2024 | E86: ACTUAL | F86: wacc | G86: 0.1 | H86: 假设初始化 | I86: WACC
A87: GROUP | C87: 华东 | D87: 2024 | E87: ACTUAL | F87: region_mix | G87: 0.32 | H87: 行业研究 | I87: 收入地区占比
A88: GROUP | C88: 华北 | D88: 2024 | E88: ACTUAL | F88: region_mix | G88: 0.3 | H88: 行业研究 | I88: 收入地区占比
A89: GROUP | C89: 华南 | D89: 2024 | E89: ACTUAL | F89: region_mix | G89: 0.2 | H89: 行业研究 | I89: 收入地区占比
A90: GROUP | C90: 海外 | D90: 2024 | E90: ACTUAL | F90: region_mix | G90: 0.18 | H90: 行业研究 | I90: 收入地区占比
A91: CLOUD | D91: 2024 | E91: ACTUAL | F91: token_volume_day | G91: 200 | H91: 假设初始化 | I91: 日均 token 消耗（B/day）
A92: CLOUD | D92: 2024 | E92: ACTUAL | F92: api_price | G92: 5 | H92: 假设初始化 | I92: 综合单价（元/M tokens）
A93: CLOUD | D93: 2024 | E93: ACTUAL | F93: inference_ucost | G93: 2.35 | H93: 假设初始化 | I93: 推理单位成本（元/M tok）
A94: CLOUD | D94: 2024 | E94: ACTUAL | F94: bandwidth_fee | G94: 700 | H94: 假设初始化 | I94: 带宽机房费用（万）
A95: CLOUD | D95: 2024 | E95: ACTUAL | F95: customers | G95: 2200 | H95: 假设初始化 | I95: 付费客户数（家）
A96: CLOUD | D96: 2024 | E96: ACTUAL | F96: churn_m | G96: 0.012 | H96: 假设初始化 | I96: 月流失率
A97: IND | D97: 2024 | E97: ACTUAL | F97: projects_pvt | G97: 14 | H97: 假设初始化 | I97: 私有化项目数（个）
A98: IND | D98: 2024 | E98: ACTUAL | F98: avg_contract | G98: 1100 | H98: 假设初始化 | I98: 平均合同额（万）
A99: IND | D99: 2024 | E99: ACTUAL | F99: subscribers_sol | G99: 30 | H99: 假设初始化 | I99: 解决方案签约客户（累计）
A100: IND | D100: 2024 | E100: ACTUAL | F100: sub_fee | G100: 100 | H100: 假设初始化 | I100: 解决方案年费（万）
A101: IND | D101: 2024 | E101: ACTUAL | F101: cogs_rate_pvt | G101: 0.61 | H101: 假设初始化 | I101: 私有化成本率
...

Sheet Assumptions
A1: 智擎集团 · 指标视图层 Assumptions
A2: 全部数值实时取自 Meta 数据表（SUMIFS）| 本页只读，改数请改 Meta!G 列 | 单位：万元
A3: 科目（万元） | B3: 备注 | C3: 2023 | D3: 2024 | E3: 2025 | F3: 2026 | G3: 2027
A4: ── 集团共用 ──
A5: 所得税率（高新15%） | C5: =SUMIFS(Meta!$G$2:$G$400,Meta!$F$2:$F$400,"tax_rate",Meta!$D$2:$D$400,C$3,Meta!$A$2:$A$400,"GROUP") | D5: =SUMIFS(Meta!$G$2:$G$400,Meta!$F$2:$F$400,"tax_rate",Meta!$D$2:$D$400,D$3,Meta!$A$2:$A$400,"GROUP") | E5: =SUMIFS(Meta!$G$2:$G$400,Meta!$F$2:$F$400,"tax_rate",Meta!$D$2:$D$400,E$3,Meta!$A$2:$A$400,"GROUP") | F5: =SUMIFS(Meta!$G$2:$G$400,Meta!$F$2:$F$400,"tax_rate",Meta!$D$2:$D$400,F$3,Meta!$A$2:$A$400,"GROUP") | G5: =SUMIFS(Meta!$G$2:$G$400,Meta!$F$2:$F$400,"tax_rate",Meta!$D$2:$D$400,G$3,Meta!$A$2:$A$400,"GROUP")
A6: 应收账期（天） | C6: =SUMIFS(Meta!$G$2:$G$400,Meta!$F$2:$F$400,"dso_days",Meta!$D$2:$D$400,C$3,Meta!$A$2:$A$400,"GROUP") | D6: =SUMIFS(Meta!$G$2:$G$400,Meta!$F$2:$F$400,"dso_days",Meta!$D$2:$D$400,D$3,Meta!$A$2:$A$400,"GROUP") | E6: =SUMIFS(Meta!$G$2:$G$400,Meta!$F$2:$F$400,"dso_days",Meta!$D$2:$D$400,E$3,Meta!$A$2:$A$400,"GROUP") | F6: =SUMIFS(Meta!$G$2:$G$400,Meta!$F$2:$F$400,"dso_days",Meta!$D$2:$D$400,F$3,Meta!$A$2:$A$400,"GROUP") | G6: =SUMIFS(Meta!$G$2:$G$400,Meta!$F$2:$F$400,"dso_days",Meta!$D$2:$D$400,G$3,Meta!$A$2:$A$400,"GROUP")
A7: 应付账期（天） | C7: =SUMIFS(Meta!$G$2:$G$400,Meta!$F$2:$F$400,"dpo_days",Meta!$D$2:$D$400,C$3,Meta!$A$2:$A$400,"GROUP") | D7: =SUMIFS(Meta!$G$2:$G$400,Meta!$F$2:$F$400,"dpo_days",Meta!$D$2:$D$400,D$3,Meta!$A$2:$A$400,"GROUP") | E7: =SUMIFS(Meta!$G$2:$G$400,Meta!$F$2:$F$400,"dpo_days",Meta!$D$2:$D$400,E$3,Meta!$A$2:$A$400,"GROUP") | F7: =SUMIFS(Meta!$G$2:$G$400,Meta!$F$2:$F$400,"dpo_days",Meta!$D$2:$D$400,F$3,Meta!$A$2:$A$400,"GROUP") | G7: =SUMIFS(Meta!$G$2:$G$400,Meta!$F$2:$F$400,"dpo_days",Meta!$D$2:$D$400,G$3,Meta!$A$2:$A$400,"GROUP")
A8: 内部往来账期（天） | C8: =SUMIFS(Meta!$G$2:$G$400,Meta!$F$2:$F$400,"ic_days",Meta!$D$2:$D$400,C$3,Meta!$A$2:$A$400,"GROUP") | D8: =SUMIFS(Meta!$G$2:$G$400,Meta!$F$2:$F$400,"ic_days",Meta!$D$2:$D$400,D$3,Meta!$A$2:$A$400,"GROUP") | E8: =SUMIFS(Meta!$G$2:$G$400,Meta!$F$2:$F$400,"ic_days",Meta!$D$2:$D$400,E$3,Meta!$A$2:$A$400,"GROUP") | F8: =SUMIFS(Meta!$G$2:$G$400,Meta!$F$2:$F$400,"ic_days",Meta!$D$2:$D$400,F$3,Meta!$A$2:$A$400,"GROUP") | G8: =SUMIFS(Meta!$G$2:$G$400,Meta!$F$2:$F$400,"ic_days",Meta!$D$2:$D$400,G$3,Meta!$A$2:$A$400,"GROUP")
A9: WACC（项目评估） | C9: =SUMIFS(Meta!$G$2:$G$400,Meta!$F$2:$F$400,"wacc",Meta!$D$2:$D$400,C$3,Meta!$A$2:$A$400,"GROUP") | D9: =SUMIFS(Meta!$G$2:$G$400,Meta!$F$2:$F$400,"wacc",Meta!$D$2:$D$400,D$3,Meta!$A$2:$A$400,"GROUP") | E9: =SUMIFS(Meta!$G$2:$G$400,Meta!$F$2:$F$400,"wacc",Meta!$D$2:$D$400,E$3,Meta!$A$2:$A$400,"GROUP") | F9: =SUMIFS(Meta!$G$2:$G$400,Meta!$F$2:$F$400,"wacc",Meta!$D$2:$D$400,F$3,Meta!$A$2:$A$400,"GROUP") | G9: =SUMIFS(Meta!$G$2:$G$400,Meta!$F$2:$F$400,"wacc",Meta!$D$2:$D$400,G$3,Meta!$A$2:$A$400,"GROUP")
A10: ── 智擎云 · MaaS ──
A11: 日均 token 消耗（B/day） | B11: 智谱 bigmodel 模式 | C11: =SUMIFS(Meta!$G$2:$G$400,Meta!$F$2:$F$400,"token_volume_day",Meta!$D$2:$D$400,C$3,Meta!$A$2:$A$400,"CLOUD") | D11: =SUMIFS(Meta!$G$2:$G$400,Meta!$F$2:$F$400,"token_volume_day",Meta!$D$2:$D$400,D$3,Meta!$A$2:$A$400,"CLOUD") | E11: =SUMIFS(Meta!$G$2:$G$400,Meta!$F$2:$F$400,"token_volume_day",Meta!$D$2:$D$400,E$3,Meta!$A$2:$A$400,"CLOUD") | F11: =SUMIFS(Meta!$G$2:$G$400,Meta!$F$2:$F$400,"token_volume_day",Meta!$D$2:$D$400,F$3,Meta!$A$2:$A$400,"CLOUD") | G11: =SUMIFS(Meta!$G$2:$G$400,Meta!$F$2:$F$400,"token_volume_day",Meta!$D$2:$D$400,G$3,Meta!$A$2:$A$400,"CLOUD")
A12: 综合单价（元/M tokens） | B12: 混合计价 | C12: =SUMIFS(Meta!$G$2:$G$400,Meta!$F$2:$F$400,"api_price",Meta!$D$2:$D$400,C$3,Meta!$A$2:$A$400,"CLOUD") | D12: =SUMIFS(Meta!$G$2:$G$400,Meta!$F$2:$F$400,"api_price",Meta!$D$2:$D$400,D$3,Meta!$A$2:$A$400,"CLOUD") | E12: =SUMIFS(Meta!$G$2:$G$400,Meta!$F$2:$F$400,"api_price",Meta!$D$2:$D$400,E$3,Meta!$A$2:$A$400,"CLOUD") | F12: =SUMIFS(Meta!$G$2:$G$400,Meta!$F$2:$F$400,"api_price",Meta!$D$2:$D$400,F$3,Meta!$A$2:$A$400,"CLOUD") | G12: =SUMIFS(Meta!$G$2:$G$400,Meta!$F$2:$F$400,"api_price",Meta!$D$2:$D$400,G$3,Meta!$A$2:$A$400,"CLOUD")
A13: 推理单位成本（元/M tokens） | B13: 自持+外租混合 | C13: =SUMIFS(Meta!$G$2:$G$400,Meta!$F$2:$F$400,"inference_ucost",Meta!$D$2:$D$400,C$3,Meta!$A$2:$A$400,"CLOUD") | D13: =SUMIFS(Meta!$G$2:$G$400,Meta!$F$2:$F$400,"inference_ucost",Meta!$D$2:$D$400,D$3,Meta!$A$2:$A$400,"CLOUD") | E13: =SUMIFS(Meta!$G$2:$G$400,Meta!$F$2:$F$400,"inference_ucost",Meta!$D$2:$D$400,E$3,Meta!$A$2:$A$400,"CLOUD") | F13: =SUMIFS(Meta!$G$2:$G$400,Meta!$F$2:$F$400,"inference_ucost",Meta!$D$2:$D$400,F$3,Meta!$A$2:$A$400,"CLOUD") | G13: =SUMIFS(Meta!$G$2:$G$400,Meta!$F$2:$F$400,"inference_ucost",Meta!$D$2:$D$400,G$3,Meta!$A$2:$A$400,"CLOUD")
A14: 带宽机房费用 | C14: =SUMIFS(Meta!$G$2:$G$400,Meta!$F$2:$F$400,"bandwidth_fee",Meta!$D$2:$D$400,C$3,Meta!$A$2:$A$400,"CLOUD") | D14: =SUMIFS(Meta!$G$2:$G$400,Meta!$F$2:$F$400,"bandwidth_fee",Meta!$D$2:$D$400,D$3,Meta!$A$2:$A$400,"CLOUD") | E14: =SUMIFS(Meta!$G$2:$G$400,Meta!$F$2:$F$400,"bandwidth_fee",Meta!$D$2:$D$400,E$3,Meta!$A$2:$A$400,"CLOUD") | F14: =SUMIFS(Meta!$G$2:$G$400,Meta!$F$2:$F$400,"bandwidth_fee",Meta!$D$2:$D$400,F$3,Meta!$A$2:$A$400,"CLOUD") | G14: =SUMIFS(Meta!$G$2:$G$400,Meta!$F$2:$F$400,"bandwidth_fee",Meta!$D$2:$D$400,G$3,Meta!$A$2:$A$400,"CLOUD")
A15: 研发编制（人） | C15: =SUMIFS(Meta!$G$2:$G$400,Meta!$F$2:$F$400,"headcount_rd",Meta!$D$2:$D$400,C$3,Meta!$A$2:$A$400,"CLOUD") | D15: =SUMIFS(Meta!$G$2:$G$400,Meta!$F$2:$F$400,"headcount_rd",Meta!$D$2:$D$400,D$3,Meta!$A$2:$A$400,"CLOUD") | E15: =SUMIFS(Meta!$G$2:$G$400,Meta!$F$2:$F$400,"headcount_rd",Meta!$D$2:$D$400,E$3,Meta!$A$2:$A$400,"CLOUD") | F15: =SUMIFS(Meta!$G$2:$G$400,Meta!$F$2:$F$400,"headcount_rd",Meta!$D$2:$D$400,F$3,Meta!$A$2:$A$400,"CLOUD") | G15: =SUMIFS(Meta!$G$2:$G$400,Meta!$F$2:$F$400,"headcount_rd",Meta!$D$2:$D$400,G$3,Meta!$A$2:$A$400,"CLOUD")
A16: 销售编制（人） | C16: =SUMIFS(Meta!$G$2:$G$400,Meta!$F$2:$F$400,"headcount_sales",Meta!$D$2:$D$400,C$3,Meta!$A$2:$A$400,"CLOUD") | D16: =SUMIFS(Meta!$G$2:$G$400,Meta!$F$2:$F$400,"headcount_sales",Meta!$D$2:$D$400,D$3,Meta!$A$2:$A$400,"CLOUD") | E16: =SUMIFS(Meta!$G$2:$G$400,Meta!$F$2:$F$400,"headcount_sales",Meta!$D$2:$D$400,E$3,Meta!$A$2:$A$400,"CLOUD") | F16: =SUMIFS(Meta!$G$2:$G$400,Meta!$F$2:$F$400,"headcount_sales",Meta!$D$2:$D$400,F$3,Meta!$A$2:$A$400,"CLOUD") | G16: =SUMIFS(Meta!$G$2:$G$400,Meta!$F$2:$F$400,"headcount_sales",Meta!$D$2:$D$400,G$3,Meta!$A$2:$A$400,"CLOUD")
A17: 管理编制（人） | C17: =SUMIFS(Meta!$G$2:$G$400,Meta!$F$2:$F$400,"headcount_gna",Meta!$D$2:$D$400,C$3,Meta!$A$2:$A$400,"CLOUD") | D17: =SUMIFS(Meta!$G$2:$G$400,Meta!$F$2:$F$400,"headcount_gna",Meta!$D$2:$D$400,D$3,Meta!$A$2:$A$400,"CLOUD") | E17: =SUMIFS(Meta!$G$2:$G$400,Meta!$F$2:$F$400,"headcount_gna",Meta!$D$2:$D$400,E$3,Meta!$A$2:$A$400,"CLOUD") | F17: =SUMIFS(Meta!$G$2:$G$400,Meta!$F$2:$F$400,"headcount_gna",Meta!$D$2:$D$400,F$3,Meta!$A$2:$A$400,"CLOUD") | G17: =SUMIFS(Meta!$G$2:$G$400,Meta!$F$2:$F$400,"headcount_gna",Meta!$D$2:$D$400,G$3,Meta!$A$2:$A$400,"CLOUD")
A18: 付费客户数（家） | B18: UE 用 | C18: =SUMIFS(Meta!$G$2:$G$400,Meta!$F$2:$F$400,"customers",Meta!$D$2:$D$400,C$3,Meta!$A$2:$A$400,"CLOUD") | D18: =SUMIFS(Meta!$G$2:$G$400,Meta!$F$2:$F$400,"customers",Meta!$D$2:$D$400,D$3,Meta!$A$2:$A$400,"CLOUD") | E18: =SUMIFS(Meta!$G$2:$G$400,Meta!$F$2:$F$400,"customers",Meta!$D$2:$D$400,E$3,Meta!$A$2:$A$400,"CLOUD") | F18: =SUMIFS(Meta!$G$2:$G$400,Meta!$F$2:$F$400,"customers",Meta!$D$2:$D$400,F$3,Meta!$A$2:$A$400,"CLOUD") | G18: =SUMIFS(Meta!$G$2:$G$400,Meta!$F$2:$F$400,"customers",Meta!$D$2:$D$400,G$3,Meta!$A$2:$A$400,"CLOUD")
A19: 月流失率 | B19: UE 用 | C19: =SUMIFS(Meta!$G$2:$G$400,Meta!$F$2:$F$400,"churn_m",Meta!$D$2:$D$400,C$3,Meta!$A$2:$A$400,"CLOUD") | D19: =SUMIFS(Meta!$G$2:$G$400,Meta!$F$2:$F$400,"churn_m",Meta!$D$2:$D$400,D$3,Meta!$A$2:$A$400,"CLOUD") | E19: =SUMIFS(Meta!$G$2:$G$400,Meta!$F$2:$F$400,"churn_m",Meta!$D$2:$D$400,E$3,Meta!$A$2:$A$400,"CLOUD") | F19: =SUMIFS(Meta!$G$2:$G$400,Meta!$F$2:$F$400,"churn_m",Meta!$D$2:$D$400,F$3,Meta!$A$2:$A$400,"CLOUD") | G19: =SUMIFS(Meta!$G$2:$G$400,Meta!$F$2:$F$400,"churn_m",Meta!$D$2:$D$400,G$3,Meta!$A$2:$A$400,"CLOUD")
A20: ── 智擎行业 · 私有化+解决方案 ──
A21: 私有化项目数（个） | C21: =SUMIFS(Meta!$G$2:$G$400,Meta!$F$2:$F$400,"projects_pvt",Meta!$D$2:$D$400,C$3,Meta!$A$2:$A$400,"IND") | D21: =SUMIFS(Meta!$G$2:$G$400,Meta!$F$2:$F$400,"projects_pvt",Meta!$D$2:$D$400,D$3,Meta!$A$2:$A$400,"IND") | E21: =SUMIFS(Meta!$G$2:$G$400,Meta!$F$2:$F$400,"projects_pvt",Meta!$D$2:$D$400,E$3,Meta!$A$2:$A$400,"IND") | F21: =SUMIFS(Meta!$G$2:$G$400,Meta!$F$2:$F$400,"projects_pvt",Meta!$D$2:$D$400,F$3,Meta!$A$2:$A$400,"IND") | G21: =SUMIFS(Meta!$G$2:$G$400,Meta!$F$2:$F$400,"projects_pvt",Meta!$D$2:$D$400,G$3,Meta!$A$2:$A$400,"IND")
A22: 平均合同额 | C22: =SUMIFS(Meta!$G$2:$G$400,Meta!$F$2:$F$400,"avg_contract",Meta!$D$2:$D$400,C$3,Meta!$A$2:$A$400,"IND") | D22: =SUMIFS(Meta!$G$2:$G$400,Meta!$F$2:$F$400,"avg_contract",Meta!$D$2:$D$400,D$3,Meta!$A$2:$A$400,"IND") | E22: =SUMIFS(Meta!$G$2:$G$400,Meta!$F$2:$F$400,"avg_contract",Meta!$D$2:$D$400,E$3,Meta!$A$2:$A$400,"IND") | F22: =SUMIFS(Meta!$G$2:$G$400,Meta!$F$2:$F$400,"avg_contract",Meta!$D$2:$D$400,F$3,Meta!$A$2:$A$400,"IND") | G22: =SUMIFS(Meta!$G$2:$G$400,Meta!$F$2:$F$400,"avg_contract",Meta!$D$2:$D$400,G$3,Meta!$A$2:$A$400,"IND")
A23: 解决方案签约客户（累计） | B23: 订阅/运维 | C23: =SUMIFS(Meta!$G$2:$G$400,Meta!$F$2:$F$400,"subscribers_sol",Meta!$D$2:$D$400,C$3,Meta!$A$2:$A$400,"IND") | D23: =SUMIFS(Meta!$G$2:$G$400,Meta!$F$2:$F$400,"subscribers_sol",Meta!$D$2:$D$400,D$3,Meta!$A$2:$A$400,"IND") | E23: =SUMIFS(Meta!$G$2:$G$400,Meta!$F$2:$F$400,"subscribers_sol",Meta!$D$2:$D$400,E$3,Meta!$A$2:$A$400,"IND") | F23: =SUMIFS(Meta!$G$2:$G$400,Meta!$F$2:$F$400,"subscribers_sol",Meta!$D$2:$D$400,F$3,Meta!$A$2:$A$400,"IND") | G23: =SUMIFS(Meta!$G$2:$G$400,Meta!$F$2:$F$400,"subscribers_sol",Meta!$D$2:$D$400,G$3,Meta!$A$2:$A$400,"IND")
A24: 解决方案年费 | C24: =SUMIFS(Meta!$G$2:$G$400,Meta!$F$2:$F$400,"sub_fee",Meta!$D$2:$D$400,C$3,Meta!$A$2:$A$400,"IND") | D24: =SUMIFS(Meta!$G$2:$G$400,Meta!$F$2:$F$400,"sub_fee",Meta!$D$2:$D$400,D$3,Meta!$A$2:$A$400,"IND") | E24: =SUMIFS(Meta!$G$2:$G$400,Meta!$F$2:$F$400,"sub_fee",Meta!$D$2:$D$400,E$3,Meta!$A$2:$A$400,"IND") | F24: =SUMIFS(Meta!$G$2:$G$400,Meta!$F$2:$F$400,"sub_fee",Meta!$D$2:$D$400,F$3,Meta!$A$2:$A$400,"IND") | G24: =SUMIFS(Meta!$G$2:$G$400,Meta!$F$2:$F$400,"sub_fee",Meta!$D$2:$D$400,G$3,Meta!$A$2:$A$400,"IND")
A25: 私有化成本率（硬件+人力） | C25: =SUMIFS(Meta!$G$2:$G$400,Meta!$F$2:$F$400,"cogs_rate_pvt",Meta!$D$2:$D$400,C$3,Meta!$A$2:$A$400,"IND") | D25: =SUMIFS(Meta!$G$2:$G$400,Meta!$F$2:$F$400,"cogs_rate_pvt",Meta!$D$2:$D$400,D$3,Meta!$A$2:$A$400,"IND") | E25: =SUMIFS(Meta!$G$2:$G$400,Meta!$F$2:$F$400,"cogs_rate_pvt",Meta!$D$2:$D$400,E$3,Meta!$A$2:$A$400,"IND") | F25: =SUMIFS(Meta!$G$2:$G$400,Meta!$F$2:$F$400,"cogs_rate_pvt",Meta!$D$2:$D$400,F$3,Meta!$A$2:$A$400,"IND") | G25: =SUMIFS(Meta!$G$2:$G$400,Meta!$F$2:$F$400,"cogs_rate_pvt",Meta!$D$2:$D$400,G$3,Meta!$A$2:$A$400,"IND")
A26: 解决方案成本率 | C26: =SUMIFS(Meta!$G$2:$G$400,Meta!$F$2:$F$400,"cogs_rate_sol",Meta!$D$2:$D$400,C$3,Meta!$A$2:$A$400,"IND") | D26: =SUMIFS(Meta!$G$2:$G$400,Meta!$F$2:$F$400,"cogs_rate_sol",Meta!$D$2:$D$400,D$3,Meta!$A$2:$A$400,"IND") | E26: =SUMIFS(Meta!$G$2:$G$400,Meta!$F$2:$F$400,"cogs_rate_sol",Meta!$D$2:$D$400,E$3,Meta!$A$2:$A$400,"IND") | F26: =SUMIFS(Meta!$G$2:$G$400,Meta!$F$2:$F$400,"cogs_rate_sol",Meta!$D$2:$D$400,F$3,Meta!$A$2:$A$400,"IND") | G26: =SUMIFS(Meta!$G$2:$G$400,Meta!$F$2:$F$400,"cogs_rate_sol",Meta!$D$2:$D$400,G$3,Meta!$A$2:$A$400,"IND")
A27: 研发编制（人） | C27: =SUMIFS(Meta!$G$2:$G$400,Meta!$F$2:$F$400,"headcount_rd",Meta!$D$2:$D$400,C$3,Meta!$A$2:$A$400,"IND") | D27: =SUMIFS(Meta!$G$2:$G$400,Meta!$F$2:$F$400,"headcount_rd",Meta!$D$2:$D$400,D$3,Meta!$A$2:$A$400,"IND") | E27: =SUMIFS(Meta!$G$2:$G$400,Meta!$F$2:$F$400,"headcount_rd",Meta!$D$2:$D$400,E$3,Meta!$A$2:$A$400,"IND") | F27: =SUMIFS(Meta!$G$2:$G$400,Meta!$F$2:$F$400,"headcount_rd",Meta!$D$2:$D$400,F$3,Meta!$A$2:$A$400,"IND") | G27: =SUMIFS(Meta!$G$2:$G$400,Meta!$F$2:$F$400,"headcount_rd",Meta!$D$2:$D$400,G$3,Meta!$A$2:$A$400,"IND")
A28: 销售编制（人） | C28: =SUMIFS(Meta!$G$2:$G$400,Meta!$F$2:$F$400,"headcount_sales",Meta!$D$2:$D$400,C$3,Meta!$A$2:$A$400,"IND") | D28: =SUMIFS(Meta!$G$2:$G$400,Meta!$F$2:$F$400,"headcount_sales",Meta!$D$2:$D$400,D$3,Meta!$A$2:$A$400,"IND") | E28: =SUMIFS(Meta!$G$2:$G$400,Meta!$F$2:$F$400,"headcount_sales",Meta!$D$2:$D$400,E$3,Meta!$A$2:$A$400,"IND") | F28: =SUMIFS(Meta!$G$2:$G$400,Meta!$F$2:$F$400,"headcount_sales",Meta!$D$2:$D$400,F$3,Meta!$A$2:$A$400,"IND") | G28: =SUMIFS(Meta!$G$2:$G$400,Meta!$F$2:$F$400,"headcount_sales",Meta!$D$2:$D$400,G$3,Meta!$A$2:$A$400,"IND")
A29: 管理编制（人） | C29: =SUMIFS(Meta!$G$2:$G$400,Meta!$F$2:$F$400,"headcount_gna",Meta!$D$2:$D$400,C$3,Meta!$A$2:$A$400,"IND") | D29: =SUMIFS(Meta!$G$2:$G$400,Meta!$F$2:$F$400,"headcount_gna",Meta!$D$2:$D$400,D$3,Meta!$A$2:$A$400,"IND") | E29: =SUMIFS(Meta!$G$2:$G$400,Meta!$F$2:$F$400,"headcount_gna",Meta!$D$2:$D$400,E$3,Meta!$A$2:$A$400,"IND") | F29: =SUMIFS(Meta!$G$2:$G$400,Meta!$F$2:$F$400,"headcount_gna",Meta!$D$2:$D$400,F$3,Meta!$A$2:$A$400,"IND") | G29: =SUMIFS(Meta!$G$2:$G$400,Meta!$F$2:$F$400,"headcount_gna",Meta!$D$2:$D$400,G$3,Meta!$A$2:$A$400,"IND")
A30: ── 智擎互联 · C端 ──
A31: MAU（万人） | C31: =SUMIFS(Meta!$G$2:$G$400,Meta!$F$2:$F$400,"mau_w",Meta!$D$2:$D$400,C$3,Meta!$A$2:$A$400,"TOC") | D31: =SUMIFS(Meta!$G$2:$G$400,Meta!$F$2:$F$400,"mau_w",Meta!$D$2:$D$400,D$3,Meta!$A$2:$A$400,"TOC") | E31: =SUMIFS(Meta!$G$2:$G$400,Meta!$F$2:$F$400,"mau_w",Meta!$D$2:$D$400,E$3,Meta!$A$2:$A$400,"TOC") | F31: =SUMIFS(Meta!$G$2:$G$400,Meta!$F$2:$F$400,"mau_w",Meta!$D$2:$D$400,F$3,Meta!$A$2:$A$400,"TOC") | G31: =SUMIFS(Meta!$G$2:$G$400,Meta!$F$2:$F$400,"mau_w",Meta!$D$2:$D$400,G$3,Meta!$A$2:$A$400,"TOC")
A32: 付费转化率 | C32: =SUMIFS(Meta!$G$2:$G$400,Meta!$F$2:$F$400,"pay_rate",Meta!$D$2:$D$400,C$3,Meta!$A$2:$A$400,"TOC") | D32: =SUMIFS(Meta!$G$2:$G$400,Meta!$F$2:$F$400,"pay_rate",Meta!$D$2:$D$400,D$3,Meta!$A$2:$A$400,"TOC") | E32: =SUMIFS(Meta!$G$2:$G$400,Meta!$F$2:$F$400,"pay_rate",Meta!$D$2:$D$400,E$3,Meta!$A$2:$A$400,"TOC") | F32: =SUMIFS(Meta!$G$2:$G$400,Meta!$F$2:$F$400,"pay_rate",Meta!$D$2:$D$400,F$3,Meta!$A$2:$A$400,"TOC") | G32: =SUMIFS(Meta!$G$2:$G$400,Meta!$F$2:$F$400,"pay_rate",Meta!$D$2:$D$400,G$3,Meta!$A$2:$A$400,"TOC")
A33: ARPPU（元/付费用户/月） | C33: =SUMIFS(Meta!$G$2:$G$400,Meta!$F$2:$F$400,"arppu",Meta!$D$2:$D$400,C$3,Meta!$A$2:$A$400,"TOC") | D33: =SUMIFS(Meta!$G$2:$G$400,Meta!$F$2:$F$400,"arppu",Meta!$D$2:$D$400,D$3,Meta!$A$2:$A$400,"TOC") | E33: =SUMIFS(Meta!$G$2:$G$400,Meta!$F$2:$F$400,"arppu",Meta!$D$2:$D$400,E$3,Meta!$A$2:$A$400,"TOC") | F33: =SUMIFS(Meta!$G$2:$G$400,Meta!$F$2:$F$400,"arppu",Meta!$D$2:$D$400,F$3,Meta!$A$2:$A$400,"TOC") | G33: =SUMIFS(Meta!$G$2:$G$400,Meta!$F$2:$F$400,"arppu",Meta!$D$2:$D$400,G$3,Meta!$A$2:$A$400,"TOC")
A34: 广告收入 | C34: =SUMIFS(Meta!$G$2:$G$400,Meta!$F$2:$F$400,"ads_rev",Meta!$D$2:$D$400,C$3,Meta!$A$2:$A$400,"TOC") | D34: =SUMIFS(Meta!$G$2:$G$400,Meta!$F$2:$F$400,"ads_rev",Meta!$D$2:$D$400,D$3,Meta!$A$2:$A$400,"TOC") | E34: =SUMIFS(Meta!$G$2:$G$400,Meta!$F$2:$F$400,"ads_rev",Meta!$D$2:$D$400,E$3,Meta!$A$2:$A$400,"TOC") | F34: =SUMIFS(Meta!$G$2:$G$400,Meta!$F$2:$F$400,"ads_rev",Meta!$D$2:$D$400,F$3,Meta!$A$2:$A$400,"TOC") | G34: =SUMIFS(Meta!$G$2:$G$400,Meta!$F$2:$F$400,"ads_rev",Meta!$D$2:$D$400,G$3,Meta!$A$2:$A$400,"TOC")
A35: 单位推理+带宽成本（元/MAU/月） | C35: =SUMIFS(Meta!$G$2:$G$400,Meta!$F$2:$F$400,"ucost_toc",Meta!$D$2:$D$400,C$3,Meta!$A$2:$A$400,"TOC") | D35: =SUMIFS(Meta!$G$2:$G$400,Meta!$F$2:$F$400,"ucost_toc",Meta!$D$2:$D$400,D$3,Meta!$A$2:$A$400,"TOC") | E35: =SUMIFS(Meta!$G$2:$G$400,Meta!$F$2:$F$400,"ucost_toc",Meta!$D$2:$D$400,E$3,Meta!$A$2:$A$400,"TOC") | F35: =SUMIFS(Meta!$G$2:$G$400,Meta!$F$2:$F$400,"ucost_toc",Meta!$D$2:$D$400,F$3,Meta!$A$2:$A$400,"TOC") | G35: =SUMIFS(Meta!$G$2:$G$400,Meta!$F$2:$F$400,"ucost_toc",Meta!$D$2:$D$400,G$3,Meta!$A$2:$A$400,"TOC")
A36: 获客成本（元/新增用户） | C36: =SUMIFS(Meta!$G$2:$G$400,Meta!$F$2:$F$400,"cac",Meta!$D$2:$D$400,C$3,Meta!$A$2:$A$400,"TOC") | D36: =SUMIFS(Meta!$G$2:$G$400,Meta!$F$2:$F$400,"cac",Meta!$D$2:$D$400,D$3,Meta!$A$2:$A$400,"TOC") | E36: =SUMIFS(Meta!$G$2:$G$400,Meta!$F$2:$F$400,"cac",Meta!$D$2:$D$400,E$3,Meta!$A$2:$A$400,"TOC") | F36: =SUMIFS(Meta!$G$2:$G$400,Meta!$F$2:$F$400,"cac",Meta!$D$2:$D$400,F$3,Meta!$A$2:$A$400,"TOC") | G36: =SUMIFS(Meta!$G$2:$G$400,Meta!$F$2:$F$400,"cac",Meta!$D$2:$D$400,G$3,Meta!$A$2:$A$400,"TOC")
A37: 新增用户=MAU增量× | B37: 补流失 | C37: =SUMIFS(Meta!$G$2:$G$400,Meta!$F$2:$F$400,"new_user_mult",Meta!$D$2:$D$400,C$3,Meta!$A$2:$A$400,"TOC") | D37: =SUMIFS(Meta!$G$2:$G$400,Meta!$F$2:$F$400,"new_user_mult",Meta!$D$2:$D$400,D$3,Meta!$A$2:$A$400,"TOC") | E37: =SUMIFS(Meta!$G$2:$G$400,Meta!$F$2:$F$400,"new_user_mult",Meta!$D$2:$D$400,E$3,Meta!$A$2:$A$400,"TOC") | F37: =SUMIFS(Meta!$G$2:$G$400,Meta!$F$2:$F$400,"new_user_mult",Meta!$D$2:$D$400,F$3,Meta!$A$2:$A$400,"TOC") | G37: =SUMIFS(Meta!$G$2:$G$400,Meta!$F$2:$F$400,"new_user_mult",Meta!$D$2:$D$400,G$3,Meta!$A$2:$A$400,"TOC")
A38: 研发编制（人） | C38: =SUMIFS(Meta!$G$2:$G$400,Meta!$F$2:$F$400,"headcount_rd",Meta!$D$2:$D$400,C$3,Meta!$A$2:$A$400,"TOC") | D38: =SUMIFS(Meta!$G$2:$G$400,Meta!$F$2:$F$400,"headcount_rd",Meta!$D$2:$D$400,D$3,Meta!$A$2:$A$400,"TOC") | E38: =SUMIFS(Meta!$G$2:$G$400,Meta!$F$2:$F$400,"headcount_rd",Meta!$D$2:$D$400,E$3,Meta!$A$2:$A$400,"TOC") | F38: =SUMIFS(Meta!$G$2:$G$400,Meta!$F$2:$F$400,"headcount_rd",Meta!$D$2:$D$400,F$3,Meta!$A$2:$A$400,"TOC") | G38: =SUMIFS(Meta!$G$2:$G$400,Meta!$F$2:$F$400,"headcount_rd",Meta!$D$2:$D$400,G$3,Meta!$A$2:$A$400,"TOC")
A39: 固定销售编制（人） | C39: =SUMIFS(Meta!$G$2:$G$400,Meta!$F$2:$F$400,"headcount_sales",Meta!$D$2:$D$400,C$3,Meta!$A$2:$A$400,"TOC") | D39: =SUMIFS(Meta!$G$2:$G$400,Meta!$F$2:$F$400,"headcount_sales",Meta!$D$2:$D$400,D$3,Meta!$A$2:$A$400,"TOC") | E39: =SUMIFS(Meta!$G$2:$G$400,Meta!$F$2:$F$400,"headcount_sales",Meta!$D$2:$D$400,E$3,Meta!$A$2:$A$400,"TOC") | F39: =SUMIFS(Meta!$G$2:$G$400,Meta!$F$2:$F$400,"headcount_sales",Meta!$D$2:$D$400,F$3,Meta!$A$2:$A$400,"TOC") | G39: =SUMIFS(Meta!$G$2:$G$400,Meta!$F$2:$F$400,"headcount_sales",Meta!$D$2:$D$400,G$3,Meta!$A$2:$A$400,"TOC")
A40: 管理编制（人） | C40: =SUMIFS(Meta!$G$2:$G$400,Meta!$F$2:$F$400,"headcount_gna",Meta!$D$2:$D$400,C$3,Meta!$A$2:$A$400,"TOC") | D40: =SUMIFS(Meta!$G$2:$G$400,Meta!$F$2:$F$400,"headcount_gna",Meta!$D$2:$D$400,D$3,Meta!$A$2:$A$400,"TOC") | E40: =SUMIFS(Meta!$G$2:$G$400,Meta!$F$2:$F$400,"headcount_gna",Meta!$D$2:$D$400,E$3,Meta!$A$2:$A$400,"TOC") | F40: =SUMIFS(Meta!$G$2:$G$400,Meta!$F$2:$F$400,"headcount_gna",Meta!$D$2:$D$400,F$3,Meta!$A$2:$A$400,"TOC") | G40: =SUMIFS(Meta!$G$2:$G$400,Meta!$F$2:$F$400,"headcount_gna",Meta!$D$2:$D$400,G$3,Meta!$A$2:$A$400,"TOC")
...

Sheet Capex_Dep
A1: GPU 资本开支与折旧引擎
A2: 批次法：购置当年起 5 年直线 | 大模型公司的资产负债表灵魂
A3: 科目（万元） | B3: 备注 | C3: 2023 | D3: 2024 | E3: 2025 | F3: 2026 | G3: 2027
A4: ── 采购计划（取自 Meta）──
A5: 训练 GPU 采购（研究院） | B5: 含期初存量并入2023批 | C5: =SUMIFS(Meta!$G$2:$G$400,Meta!$F$2:$F$400,"capex_gpu",Meta!$D$2:$D$400,C$3,Meta!$A$2:$A$400,"HOLD") | D5: =SUMIFS(Meta!$G$2:$G$400,Meta!$F$2:$F$400,"capex_gpu",Meta!$D$2:$D$400,D$3,Meta!$A$2:$A$400,"HOLD") | E5: =SUMIFS(Meta!$G$2:$G$400,Meta!$F$2:$F$400,"capex_gpu",Meta!$D$2:$D$400,E$3,Meta!$A$2:$A$400,"HOLD") | F5: =SUMIFS(Meta!$G$2:$G$400,Meta!$F$2:$F$400,"capex_gpu",Meta!$D$2:$D$400,F$3,Meta!$A$2:$A$400,"HOLD") | G5: =SUMIFS(Meta!$G$2:$G$400,Meta!$F$2:$F$400,"capex_gpu",Meta!$D$2:$D$400,G$3,Meta!$A$2:$A$400,"HOLD")
A6: 推理 GPU 采购（智擎云） | C6: =SUMIFS(Meta!$G$2:$G$400,Meta!$F$2:$F$400,"capex_gpu",Meta!$D$2:$D$400,C$3,Meta!$A$2:$A$400,"CLOUD") | D6: =SUMIFS(Meta!$G$2:$G$400,Meta!$F$2:$F$400,"capex_gpu",Meta!$D$2:$D$400,D$3,Meta!$A$2:$A$400,"CLOUD") | E6: =SUMIFS(Meta!$G$2:$G$400,Meta!$F$2:$F$400,"capex_gpu",Meta!$D$2:$D$400,E$3,Meta!$A$2:$A$400,"CLOUD") | F6: =SUMIFS(Meta!$G$2:$G$400,Meta!$F$2:$F$400,"capex_gpu",Meta!$D$2:$D$400,F$3,Meta!$A$2:$A$400,"CLOUD") | G6: =SUMIFS(Meta!$G$2:$G$400,Meta!$F$2:$F$400,"capex_gpu",Meta!$D$2:$D$400,G$3,Meta!$A$2:$A$400,"CLOUD")
A8: ── 批次折旧明细（H列=批次原值[取自Meta]，B列=购置年）──
A9: 训练卡 2023批 | B9: 2023 | C9: =IF(AND(C$3>=$B9,C$3<$B9+5),$H9/5,0) | D9: =IF(AND(D$3>=$B9,D$3<$B9+5),$H9/5,0) | E9: =IF(AND(E$3>=$B9,E$3<$B9+5),$H9/5,0) | F9: =IF(AND(F$3>=$B9,F$3<$B9+5),$H9/5,0) | G9: =IF(AND(G$3>=$B9,G$3<$B9+5),$H9/5,0) | H9: =SUMIFS(Meta!$G$2:$G$400,Meta!$F$2:$F$400,"open_fa",Meta!$D$2:$D$400,C$3,Meta!$A$2:$A$400,"HOLD")+SUMIFS(Meta!$G$2:$G$400,Meta!$F$2:$F$400,"capex_gpu",Meta!$D$2:$D$400,C$3,Meta!$A$2:$A$400,"HOLD")
A10: 训练卡 2024批 | B10: 2024 | C10: =IF(AND(C$3>=$B10,C$3<$B10+5),$H10/5,0) | D10: =IF(AND(D$3>=$B10,D$3<$B10+5),$H10/5,0) | E10: =IF(AND(E$3>=$B10,E$3<$B10+5),$H10/5,0) | F10: =IF(AND(F$3>=$B10,F$3<$B10+5),$H10/5,0) | G10: =IF(AND(G$3>=$B10,G$3<$B10+5),$H10/5,0) | H10: =SUMIFS(Meta!$G$2:$G$400,Meta!$F$2:$F$400,"capex_gpu",Meta!$D$2:$D$400,D$3,Meta!$A$2:$A$400,"HOLD")
A11: 训练卡 2025批 | B11: 2025 | C11: =IF(AND(C$3>=$B11,C$3<$B11+5),$H11/5,0) | D11: =IF(AND(D$3>=$B11,D$3<$B11+5),$H11/5,0) | E11: =IF(AND(E$3>=$B11,E$3<$B11+5),$H11/5,0) | F11: =IF(AND(F$3>=$B11,F$3<$B11+5),$H11/5,0) | G11: =IF(AND(G$3>=$B11,G$3<$B11+5),$H11/5,0) | H11: =SUMIFS(Meta!$G$2:$G$400,Meta!$F$2:$F$400,"capex_gpu",Meta!$D$2:$D$400,E$3,Meta!$A$2:$A$400,"HOLD")
A12: 训练卡 2026批 | B12: 2026 | C12: =IF(AND(C$3>=$B12,C$3<$B12+5),$H12/5,0) | D12: =IF(AND(D$3>=$B12,D$3<$B12+5),$H12/5,0) | E12: =IF(AND(E$3>=$B12,E$3<$B12+5),$H12/5,0) | F12: =IF(AND(F$3>=$B12,F$3<$B12+5),$H12/5,0) | G12: =IF(AND(G$3>=$B12,G$3<$B12+5),$H12/5,0) | H12: =SUMIFS(Meta!$G$2:$G$400,Meta!$F$2:$F$400,"capex_gpu",Meta!$D$2:$D$400,F$3,Meta!$A$2:$A$400,"HOLD")
A13: 训练卡 2027批 | B13: 2027 | C13: =IF(AND(C$3>=$B13,C$3<$B13+5),$H13/5,0) | D13: =IF(AND(D$3>=$B13,D$3<$B13+5),$H13/5,0) | E13: =IF(AND(E$3>=$B13,E$3<$B13+5),$H13/5,0) | F13: =IF(AND(F$3>=$B13,F$3<$B13+5),$H13/5,0) | G13: =IF(AND(G$3>=$B13,G$3<$B13+5),$H13/5,0) | H13: =SUMIFS(Meta!$G$2:$G$400,Meta!$F$2:$F$400,"capex_gpu",Meta!$D$2:$D$400,G$3,Meta!$A$2:$A$400,"HOLD")
A15: 推理卡 2023批 | B15: 2023 | C15: =IF(AND(C$3>=$B15,C$3<$B15+5),$H15/5,0) | D15: =IF(AND(D$3>=$B15,D$3<$B15+5),$H15/5,0) | E15: =IF(AND(E$3>=$B15,E$3<$B15+5),$H15/5,0) | F15: =IF(AND(F$3>=$B15,F$3<$B15+5),$H15/5,0) | G15: =IF(AND(G$3>=$B15,G$3<$B15+5),$H15/5,0) | H15: =SUMIFS(Meta!$G$2:$G$400,Meta!$F$2:$F$400,"open_fa",Meta!$D$2:$D$400,C$3,Meta!$A$2:$A$400,"CLOUD")+SUMIFS(Meta!$G$2:$G$400,Meta!$F$2:$F$400,"capex_gpu",Meta!$D$2:$D$400,C$3,Meta!$A$2:$A$400,"CLOUD")
A16: 推理卡 2024批 | B16: 2024 | C16: =IF(AND(C$3>=$B16,C$3<$B16+5),$H16/5,0) | D16: =IF(AND(D$3>=$B16,D$3<$B16+5),$H16/5,0) | E16: =IF(AND(E$3>=$B16,E$3<$B16+5),$H16/5,0) | F16: =IF(AND(F$3>=$B16,F$3<$B16+5),$H16/5,0) | G16: =IF(AND(G$3>=$B16,G$3<$B16+5),$H16/5,0) | H16: =SUMIFS(Meta!$G$2:$G$400,Meta!$F$2:$F$400,"capex_gpu",Meta!$D$2:$D$400,D$3,Meta!$A$2:$A$400,"CLOUD")
A17: 推理卡 2025批 | B17: 2025 | C17: =IF(AND(C$3>=$B17,C$3<$B17+5),$H17/5,0) | D17: =IF(AND(D$3>=$B17,D$3<$B17+5),$H17/5,0) | E17: =IF(AND(E$3>=$B17,E$3<$B17+5),$H17/5,0) | F17: =IF(AND(F$3>=$B17,F$3<$B17+5),$H17/5,0) | G17: =IF(AND(G$3>=$B17,G$3<$B17+5),$H17/5,0) | H17: =SUMIFS(Meta!$G$2:$G$400,Meta!$F$2:$F$400,"capex_gpu",Meta!$D$2:$D$400,E$3,Meta!$A$2:$A$400,"CLOUD")
A18: 推理卡 2026批 | B18: 2026 | C18: =IF(AND(C$3>=$B18,C$3<$B18+5),$H18/5,0) | D18: =IF(AND(D$3>=$B18,D$3<$B18+5),$H18/5,0) | E18: =IF(AND(E$3>=$B18,E$3<$B18+5),$H18/5,0) | F18: =IF(AND(F$3>=$B18,F$3<$B18+5),$H18/5,0) | G18: =IF(AND(G$3>=$B18,G$3<$B18+5),$H18/5,0) | H18: =SUMIFS(Meta!$G$2:$G$400,Meta!$F$2:$F$400,"capex_gpu",Meta!$D$2:$D$400,F$3,Meta!$A$2:$A$400,"CLOUD")
A19: 推理卡 2027批 | B19: 2027 | C19: =IF(AND(C$3>=$B19,C$3<$B19+5),$H19/5,0) | D19: =IF(AND(D$3>=$B19,D$3<$B19+5),$H19/5,0) | E19: =IF(AND(E$3>=$B19,E$3<$B19+5),$H19/5,0) | F19: =IF(AND(F$3>=$B19,F$3<$B19+5),$H19/5,0) | G19: =IF(AND(G$3>=$B19,G$3<$B19+5),$H19/5,0) | H19: =SUMIFS(Meta!$G$2:$G$400,Meta!$F$2:$F$400,"capex_gpu",Meta!$D$2:$D$400,G$3,Meta!$A$2:$A$400,"CLOUD")
A21: ── 汇总 ──
A22: 训练 GPU 当年折旧 | B22: → 研究院研发费用 | C22: =SUM(C9:C13) | D22: =SUM(D9:D13) | E22: =SUM(E9:E13) | F22: =SUM(F9:F13) | G22: =SUM(G9:G13)
A23: 训练 GPU 净值 | B23: → 研究院 BS | C23: =SUMIFS($H$9:$H$13,$B$9:$B$13,"<="&C$3)-SUM($C$22:C22) | D23: =SUMIFS($H$9:$H$13,$B$9:$B$13,"<="&D$3)-SUM($C$22:D22) | E23: =SUMIFS($H$9:$H$13,$B$9:$B$13,"<="&E$3)-SUM($C$22:E22) | F23: =SUMIFS($H$9:$H$13,$B$9:$B$13,"<="&F$3)-SUM($C$22:F22) | G23: =SUMIFS($H$9:$H$13,$B$9:$B$13,"<="&G$3)-SUM($C$22:G22)
A24: 推理 GPU 当年折旧 | B24: → 智擎云 COGS 构成 | C24: =SUM(C15:C19) | D24: =SUM(D15:D19) | E24: =SUM(E15:E19) | F24: =SUM(F15:F19) | G24: =SUM(G15:G19)
A25: 推理 GPU 净值 | B25: → 智擎云 BS | C25: =SUMIFS($H$15:$H$19,$B$15:$B$19,"<="&C$3)-SUM($C$24:C24) | D25: =SUMIFS($H$15:$H$19,$B$15:$B$19,"<="&D$3)-SUM($C$24:D24) | E25: =SUMIFS($H$15:$H$19,$B$15:$B$19,"<="&E$3)-SUM($C$24:E24) | F25: =SUMIFS($H$15:$H$19,$B$15:$B$19,"<="&F$3)-SUM($C$24:F24) | G25: =SUMIFS($H$15:$H$19,$B$15:$B$19,"<="&G$3)-SUM($C$24:G24)
A27: ★ 引擎自检（折旧/净值 vs 影子值，应全 0）
A28: diff DEP_TRAIN | B28: 绿=0 | C28: =C22-(17000.000000) | D28: =D22-(29000.000000) | E28: =E22-(35000.000000) | F28: =F22-(38000.000000) | G28: =G22-(41000.000000)
A29: diff NET_TRAIN | B29: 绿=0 | C29: =C23-(68000.000000) | D29: =D23-(99000.000000) | E29: =E23-(94000.000000) | F29: =F23-(71000.000000) | G29: =G23-(45000.000000)
A30: diff DEP_INFER | B30: 绿=0 | C30: =C24-(7000.000000) | D30: =D24-(13000.000000) | E30: =E24-(19000.000000) | F30: =F24-(22000.000000) | G30: =G24-(24000.000000)
A31: diff NET_INFER | B31: 绿=0 | C31: =C25-(28000.000000) | D31: =D25-(45000.000000) | E31: =E25-(56000.000000) | F31: =F25-(49000.000000) | G31: =G25-(35000.000000)

Sheet Cloud_IS
A1: 智擎云 · 利润表
A2: 单体 | MaaS API：token 量 × 单价 | 万元
A3: 科目（万元） | B3: 备注 | C3: 2023 | D3: 2024 | E3: 2025 | F3: 2026 | G3: 2027
A4: 对外收入 · MaaS API | B4: 日均token×365×单价/1000 | C4: =Assumptions!C11*36.5*Assumptions!C12 | D4: =Assumptions!D11*36.5*Assumptions!D12 | E4: =Assumptions!E11*36.5*Assumptions!E12 | F4: =Assumptions!F11*36.5*Assumptions!F12 | G4: =Assumptions!G11*36.5*Assumptions!G12
A5: 关联收入 · T3 算力服务（互联） | B5: 互联推理成本×70% | C5: =Assumptions!C31*Assumptions!C35*12*Assumptions!C52 | D5: =Assumptions!D31*Assumptions!D35*12*Assumptions!D52 | E5: =Assumptions!E31*Assumptions!E35*12*Assumptions!E52 | F5: =Assumptions!F31*Assumptions!F35*12*Assumptions!F52 | G5: =Assumptions!G31*Assumptions!G35*12*Assumptions!G52
A6: 营业收入合计 | C6: =Cloud_IS!C4+Cloud_IS!C5 | D6: =Cloud_IS!D4+Cloud_IS!D5 | E6: =Cloud_IS!E4+Cloud_IS!E5 | F6: =Cloud_IS!F4+Cloud_IS!F5 | G6: =Cloud_IS!G4+Cloud_IS!G5
A7: 成本 · 推理算力（对外部分） | C7: =Assumptions!C11*36.5*Assumptions!C13 | D7: =Assumptions!D11*36.5*Assumptions!D13 | E7: =Assumptions!E11*36.5*Assumptions!E13 | F7: =Assumptions!F11*36.5*Assumptions!F13 | G7: =Assumptions!G11*36.5*Assumptions!G13
A8: 成本 · T3 服务成本 | B8: 内部价毛利率45% | C8: =Cloud_IS!C5*(1-Assumptions!C53) | D8: =Cloud_IS!D5*(1-Assumptions!D53) | E8: =Cloud_IS!E5*(1-Assumptions!E53) | F8: =Cloud_IS!F5*(1-Assumptions!F53) | G8: =Cloud_IS!G5*(1-Assumptions!G53)
A9: 成本 · 带宽机房 | C9: =Assumptions!C14 | D9: =Assumptions!D14 | E9: =Assumptions!E14 | F9: =Assumptions!F14 | G9: =Assumptions!G14
A10: 成本 · T1 license 费 | C10: =Cloud_IS!C4*Assumptions!C48 | D10: =Cloud_IS!D4*Assumptions!D48 | E10: =Cloud_IS!E4*Assumptions!E48 | F10: =Cloud_IS!F4*Assumptions!F48 | G10: =Cloud_IS!G4*Assumptions!G48
A11: 营业成本合计 | C11: =SUM(Cloud_IS!C7,Cloud_IS!C8,Cloud_IS!C9,Cloud_IS!C10) | D11: =SUM(Cloud_IS!D7,Cloud_IS!D8,Cloud_IS!D9,Cloud_IS!D10) | E11: =SUM(Cloud_IS!E7,Cloud_IS!E8,Cloud_IS!E9,Cloud_IS!E10) | F11: =SUM(Cloud_IS!F7,Cloud_IS!F8,Cloud_IS!F9,Cloud_IS!F10) | G11: =SUM(Cloud_IS!G7,Cloud_IS!G8,Cloud_IS!G9,Cloud_IS!G10)
A12: 毛利润 | C12: =Cloud_IS!C6-Cloud_IS!C11 | D12: =Cloud_IS!D6-Cloud_IS!D11 | E12: =Cloud_IS!E6-Cloud_IS!E11 | F12: =Cloud_IS!F6-Cloud_IS!F11 | G12: =Cloud_IS!G6-Cloud_IS!G11
A13: 研发费用 | B13: 编制×人均70万 | C13: =Assumptions!C15*70 | D13: =Assumptions!D15*70 | E13: =Assumptions!E15*70 | F13: =Assumptions!F15*70 | G13: =Assumptions!G15*70
A14: 销售费用 | B14: ×60万 | C14: =Assumptions!C16*60 | D14: =Assumptions!D16*60 | E14: =Assumptions!E16*60 | F14: =Assumptions!F16*60 | G14: =Assumptions!G16*60
A15: 管理费用 | B15: ×55万 | C15: =Assumptions!C17*55 | D15: =Assumptions!D17*55 | E15: =Assumptions!E17*55 | F15: =Assumptions!F17*55 | G15: =Assumptions!G17*55
A16: EBIT | C16: =Cloud_IS!C12-Cloud_IS!C13-Cloud_IS!C14-Cloud_IS!C15 | D16: =Cloud_IS!D12-Cloud_IS!D13-Cloud_IS!D14-Cloud_IS!D15 | E16: =Cloud_IS!E12-Cloud_IS!E13-Cloud_IS!E14-Cloud_IS!E15 | F16: =Cloud_IS!F12-Cloud_IS!F13-Cloud_IS!F14-Cloud_IS!F15 | G16: =Cloud_IS!G12-Cloud_IS!G13-Cloud_IS!G14-Cloud_IS!G15
A17: 所得税 | C17: =MAX(0,Cloud_IS!C16)*Assumptions!C5 | D17: =MAX(0,Cloud_IS!D16)*Assumptions!D5 | E17: =MAX(0,Cloud_IS!E16)*Assumptions!E5 | F17: =MAX(0,Cloud_IS!F16)*Assumptions!F5 | G17: =MAX(0,Cloud_IS!G16)*Assumptions!G5
A18: 净利润 | C18: =Cloud_IS!C16-Cloud_IS!C17 | D18: =Cloud_IS!D16-Cloud_IS!D17 | E18: =Cloud_IS!E16-Cloud_IS!E17 | F18: =Cloud_IS!F16-Cloud_IS!F17 | G18: =Cloud_IS!G16-Cloud_IS!G17

Sheet Cloud_BS_CF
A1: 智擎云 · 资产负债表+现金流量表
A2: 单体半厚 | BS在上 CF在下 | 万元
A3: 科目（万元） | B3: 备注 | C3: 2023 | D3: 2024 | E3: 2025 | F3: 2026 | G3: 2027
A4: ── 资产负债表（关键科目）──
A5: 应收账款 | C5: =Cloud_IS!C4*Assumptions!C6/365 | D5: =Cloud_IS!D4*Assumptions!D6/365 | E5: =Cloud_IS!E4*Assumptions!E6/365 | F5: =Cloud_IS!F4*Assumptions!F6/365 | G5: =Cloud_IS!G4*Assumptions!G6/365
A6: 内部应收（互联 T3） | B6: 2027 含 cut-off 未开票 −220 | C6: =(Assumptions!C31*Assumptions!C35*12*Assumptions!C52)*Assumptions!C8/365 | D6: =(Assumptions!D31*Assumptions!D35*12*Assumptions!D52)*Assumptions!D8/365 | E6: =(Assumptions!E31*Assumptions!E35*12*Assumptions!E52)*Assumptions!E8/365 | F6: =(Assumptions!F31*Assumptions!F35*12*Assumptions!F52)*Assumptions!F8/365 | G6: =(Assumptions!G31*Assumptions!G35*12*Assumptions!G52)*Assumptions!G8/365-Assumptions!G54
A7: 固定资产 · 推理 GPU 净值 | C7: =Capex_Dep!C25 | D7: =Capex_Dep!D25 | E7: =Capex_Dep!E25 | F7: =Capex_Dep!F25 | G7: =Capex_Dep!G25
A8: 非现金资产合计 | C8: =Cloud_BS_CF!C5+Cloud_BS_CF!C6+Cloud_BS_CF!C7 | D8: =Cloud_BS_CF!D5+Cloud_BS_CF!D6+Cloud_BS_CF!D7 | E8: =Cloud_BS_CF!E5+Cloud_BS_CF!E6+Cloud_BS_CF!E7 | F8: =Cloud_BS_CF!F5+Cloud_BS_CF!F6+Cloud_BS_CF!F7 | G8: =Cloud_BS_CF!G5+Cloud_BS_CF!G6+Cloud_BS_CF!G7
A9: 应付账款 | C9: =(Cloud_IS!C11+Cloud_IS!C13+Cloud_IS!C14+Cloud_IS!C15-Capex_Dep!C24)*Assumptions!C7/365 | D9: =(Cloud_IS!D11+Cloud_IS!D13+Cloud_IS!D14+Cloud_IS!D15-Capex_Dep!D24)*Assumptions!D7/365 | E9: =(Cloud_IS!E11+Cloud_IS!E13+Cloud_IS!E14+Cloud_IS!E15-Capex_Dep!E24)*Assumptions!E7/365 | F9: =(Cloud_IS!F11+Cloud_IS!F13+Cloud_IS!F14+Cloud_IS!F15-Capex_Dep!F24)*Assumptions!F7/365 | G9: =(Cloud_IS!G11+Cloud_IS!G13+Cloud_IS!G14+Cloud_IS!G15-Capex_Dep!G24)*Assumptions!G7/365
A10: 内部应付（研究院 T1） | C10: =Cloud_IS!C10*Assumptions!C8/365 | D10: =Cloud_IS!D10*Assumptions!D8/365 | E10: =Cloud_IS!E10*Assumptions!E8/365 | F10: =Cloud_IS!F10*Assumptions!F8/365 | G10: =Cloud_IS!G10*Assumptions!G8/365
A11: 递延收益 | C11: =Cloud_IS!C6*Assumptions!C77 | D11: =Cloud_IS!D6*Assumptions!D77 | E11: =Cloud_IS!E6*Assumptions!E77 | F11: =Cloud_IS!F6*Assumptions!F77 | G11: =Cloud_IS!G6*Assumptions!G77
A12: 负债合计 | C12: =Cloud_BS_CF!C9+Cloud_BS_CF!C10+Cloud_BS_CF!C11 | D12: =Cloud_BS_CF!D9+Cloud_BS_CF!D10+Cloud_BS_CF!D11 | E12: =Cloud_BS_CF!E9+Cloud_BS_CF!E10+Cloud_BS_CF!E11 | F12: =Cloud_BS_CF!F9+Cloud_BS_CF!F10+Cloud_BS_CF!F11 | G12: =Cloud_BS_CF!G9+Cloud_BS_CF!G10+Cloud_BS_CF!G11
A13: 实收资本 | C13: =Assumptions!C69+Assumptions!C57 | D13: =C13+Assumptions!D57 | E13: =D13+Assumptions!E57 | F13: =E13+Assumptions!F57 | G13: =F13+Assumptions!G57
A14: 未分配利润 | C14: =Assumptions!C68+Cloud_IS!C18 | D14: =C14+Cloud_IS!D18 | E14: =D14+Cloud_IS!E18 | F14: =E14+Cloud_IS!F18 | G14: =F14+Cloud_IS!G18
A15: 货币资金（倒挤） | C15: =Cloud_BS_CF!C12+Cloud_BS_CF!C13+Cloud_BS_CF!C14-Cloud_BS_CF!C8 | D15: =Cloud_BS_CF!D12+Cloud_BS_CF!D13+Cloud_BS_CF!D14-Cloud_BS_CF!D8 | E15: =Cloud_BS_CF!E12+Cloud_BS_CF!E13+Cloud_BS_CF!E14-Cloud_BS_CF!E8 | F15: =Cloud_BS_CF!F12+Cloud_BS_CF!F13+Cloud_BS_CF!F14-Cloud_BS_CF!F8 | G15: =Cloud_BS_CF!G12+Cloud_BS_CF!G13+Cloud_BS_CF!G14-Cloud_BS_CF!G8
A16: ── 现金流量表（间接法）──
A17: 净利润 | C17: =Cloud_IS!C18 | D17: =Cloud_IS!D18 | E17: =Cloud_IS!E18 | F17: =Cloud_IS!F18 | G17: =Cloud_IS!G18
A18: 加：折旧 | C18: =Capex_Dep!C24 | D18: =Capex_Dep!D24 | E18: =Capex_Dep!E24 | F18: =Capex_Dep!F24 | G18: =Capex_Dep!G24
A19: 减：应收增加 | C19: =-(Cloud_BS_CF!C5-(0)) | D19: =-(Cloud_BS_CF!D5-(Cloud_BS_CF!C5)) | E19: =-(Cloud_BS_CF!E5-(Cloud_BS_CF!D5)) | F19: =-(Cloud_BS_CF!F5-(Cloud_BS_CF!E5)) | G19: =-(Cloud_BS_CF!G5-(Cloud_BS_CF!F5))
A20: 内部往来净变动 | C20: =(Cloud_BS_CF!C10-(0))-(Cloud_BS_CF!C6-(0)) | D20: =(Cloud_BS_CF!D10-(Cloud_BS_CF!C10))-(Cloud_BS_CF!D6-(Cloud_BS_CF!C6)) | E20: =(Cloud_BS_CF!E10-(Cloud_BS_CF!D10))-(Cloud_BS_CF!E6-(Cloud_BS_CF!D6)) | F20: =(Cloud_BS_CF!F10-(Cloud_BS_CF!E10))-(Cloud_BS_CF!F6-(Cloud_BS_CF!E6)) | G20: =(Cloud_BS_CF!G10-(Cloud_BS_CF!F10))-(Cloud_BS_CF!G6-(Cloud_BS_CF!F6))
A21: 加：递延增加 | C21: =Cloud_BS_CF!C11-(0) | D21: =Cloud_BS_CF!D11-(Cloud_BS_CF!C11) | E21: =Cloud_BS_CF!E11-(Cloud_BS_CF!D11) | F21: =Cloud_BS_CF!F11-(Cloud_BS_CF!E11) | G21: =Cloud_BS_CF!G11-(Cloud_BS_CF!F11)
A22: 加：应付增加 | C22: =Cloud_BS_CF!C9-(0) | D22: =Cloud_BS_CF!D9-(Cloud_BS_CF!C9) | E22: =Cloud_BS_CF!E9-(Cloud_BS_CF!D9) | F22: =Cloud_BS_CF!F9-(Cloud_BS_CF!E9) | G22: =Cloud_BS_CF!G9-(Cloud_BS_CF!F9)
A23: 经营现金流 | C23: =Cloud_BS_CF!C17+Cloud_BS_CF!C18+Cloud_BS_CF!C19+Cloud_BS_CF!C20+Cloud_BS_CF!C21+Cloud_BS_CF!C22 | D23: =Cloud_BS_CF!D17+Cloud_BS_CF!D18+Cloud_BS_CF!D19+Cloud_BS_CF!D20+Cloud_BS_CF!D21+Cloud_BS_CF!D22 | E23: =Cloud_BS_CF!E17+Cloud_BS_CF!E18+Cloud_BS_CF!E19+Cloud_BS_CF!E20+Cloud_BS_CF!E21+Cloud_BS_CF!E22 | F23: =Cloud_BS_CF!F17+Cloud_BS_CF!F18+Cloud_BS_CF!F19+Cloud_BS_CF!F20+Cloud_BS_CF!F21+Cloud_BS_CF!F22 | G23: =Cloud_BS_CF!G17+Cloud_BS_CF!G18+Cloud_BS_CF!G19+Cloud_BS_CF!G20+Cloud_BS_CF!G21+Cloud_BS_CF!G22
A24: 投资现金流 | C24: =-Capex_Dep!C6 | D24: =-Capex_Dep!D6 | E24: =-Capex_Dep!E6 | F24: =-Capex_Dep!F6 | G24: =-Capex_Dep!G6
A25: 筹资：股权注资 | C25: =Assumptions!C57 | D25: =Assumptions!D57 | E25: =Assumptions!E57 | F25: =Assumptions!F57 | G25: =Assumptions!G57
A26: 现金净变动 | C26: =Cloud_BS_CF!C23+Cloud_BS_CF!C24+Cloud_BS_CF!C25 | D26: =Cloud_BS_CF!D23+Cloud_BS_CF!D24+Cloud_BS_CF!D25 | E26: =Cloud_BS_CF!E23+Cloud_BS_CF!E24+Cloud_BS_CF!E25 | F26: =Cloud_BS_CF!F23+Cloud_BS_CF!F24+Cloud_BS_CF!F25 | G26: =Cloud_BS_CF!G23+Cloud_BS_CF!G24+Cloud_BS_CF!G25
A27: 期末现金（CF） | C27: =10000+Cloud_BS_CF!C26 | D27: =C27+Cloud_BS_CF!D26 | E27: =D27+Cloud_BS_CF!E26 | F27: =E27+Cloud_BS_CF!F26 | G27: =F27+Cloud_BS_CF!G26
A28: ★ CF=BS 差异（应全 0）
A29: CF推导 − BS倒挤 | C29: =Cloud_BS_CF!C27-Cloud_BS_CF!C15 | D29: =Cloud_BS_CF!D27-Cloud_BS_CF!D15 | E29: =Cloud_BS_CF!E27-Cloud_BS_CF!E15 | F29: =Cloud_BS_CF!F27-Cloud_BS_CF!F15 | G29: =Cloud_BS_CF!G27-Cloud_BS_CF!G15

Sheet Ind_IS
A1: 智擎行业 · 利润表
A2: 单体 | 私有化部署 + 行业解决方案 双业务线 | 万元
A3: 科目（万元） | B3: 备注 | C3: 2023 | D3: 2024 | E3: 2025 | F3: 2026 | G3: 2027
A4: 收入 · 私有化部署 | B4: 项目数×合同额 | C4: =Assumptions!C21*Assumptions!C22 | D4: =Assumptions!D21*Assumptions!D22 | E4: =Assumptions!E21*Assumptions!E22 | F4: =Assumptions!F21*Assumptions!F22 | G4: =Assumptions!G21*Assumptions!G22
A5: 收入 · 行业解决方案 | B5: 签约客户×年费 | C5: =Assumptions!C23*Assumptions!C24 | D5: =Assumptions!D23*Assumptions!D24 | E5: =Assumptions!E23*Assumptions!E24 | F5: =Assumptions!F23*Assumptions!F24 | G5: =Assumptions!G23*Assumptions!G24
A6: 对外收入合计 | C6: =Ind_IS!C4+Ind_IS!C5 | D6: =Ind_IS!D4+Ind_IS!D5 | E6: =Ind_IS!E4+Ind_IS!E5 | F6: =Ind_IS!F4+Ind_IS!F5 | G6: =Ind_IS!G4+Ind_IS!G5
A7: 成本 · 私有化（硬件+人力） | C7: =Ind_IS!C4*Assumptions!C25 | D7: =Ind_IS!D4*Assumptions!D25 | E7: =Ind_IS!E4*Assumptions!E25 | F7: =Ind_IS!F4*Assumptions!F25 | G7: =Ind_IS!G4*Assumptions!G25
A8: 成本 · 解决方案 | C8: =Ind_IS!C5*Assumptions!C26 | D8: =Ind_IS!D5*Assumptions!D26 | E8: =Ind_IS!E5*Assumptions!E26 | F8: =Ind_IS!F5*Assumptions!F26 | G8: =Ind_IS!G5*Assumptions!G26
A9: 成本 · T1 license 费 | C9: =Ind_IS!C6*Assumptions!C49 | D9: =Ind_IS!D6*Assumptions!D49 | E9: =Ind_IS!E6*Assumptions!E49 | F9: =Ind_IS!F6*Assumptions!F49 | G9: =Ind_IS!G6*Assumptions!G49
A10: 成本 · T2 定制研发 | C10: =Assumptions!C51 | D10: =Assumptions!D51 | E10: =Assumptions!E51 | F10: =Assumptions!F51 | G10: =Assumptions!G51
A11: 营业成本合计 | C11: =SUM(Ind_IS!C7,Ind_IS!C8,Ind_IS!C9,Ind_IS!C10) | D11: =SUM(Ind_IS!D7,Ind_IS!D8,Ind_IS!D9,Ind_IS!D10) | E11: =SUM(Ind_IS!E7,Ind_IS!E8,Ind_IS!E9,Ind_IS!E10) | F11: =SUM(Ind_IS!F7,Ind_IS!F8,Ind_IS!F9,Ind_IS!F10) | G11: =SUM(Ind_IS!G7,Ind_IS!G8,Ind_IS!G9,Ind_IS!G10)
A12: 毛利润 | C12: =Ind_IS!C6-Ind_IS!C11 | D12: =Ind_IS!D6-Ind_IS!D11 | E12: =Ind_IS!E6-Ind_IS!E11 | F12: =Ind_IS!F6-Ind_IS!F11 | G12: =Ind_IS!G6-Ind_IS!G11
A13: 研发费用 | B13: ×70万 | C13: =Assumptions!C27*70 | D13: =Assumptions!D27*70 | E13: =Assumptions!E27*70 | F13: =Assumptions!F27*70 | G13: =Assumptions!G27*70
A14: 销售费用 | B14: ×60万 | C14: =Assumptions!C28*60 | D14: =Assumptions!D28*60 | E14: =Assumptions!E28*60 | F14: =Assumptions!F28*60 | G14: =Assumptions!G28*60
A15: 管理费用 | B15: ×55万 | C15: =Assumptions!C29*55 | D15: =Assumptions!D29*55 | E15: =Assumptions!E29*55 | F15: =Assumptions!F29*55 | G15: =Assumptions!G29*55
A16: EBIT | C16: =Ind_IS!C12-Ind_IS!C13-Ind_IS!C14-Ind_IS!C15 | D16: =Ind_IS!D12-Ind_IS!D13-Ind_IS!D14-Ind_IS!D15 | E16: =Ind_IS!E12-Ind_IS!E13-Ind_IS!E14-Ind_IS!E15 | F16: =Ind_IS!F12-Ind_IS!F13-Ind_IS!F14-Ind_IS!F15 | G16: =Ind_IS!G12-Ind_IS!G13-Ind_IS!G14-Ind_IS!G15
A17: 所得税 | C17: =MAX(0,Ind_IS!C16)*Assumptions!C5 | D17: =MAX(0,Ind_IS!D16)*Assumptions!D5 | E17: =MAX(0,Ind_IS!E16)*Assumptions!E5 | F17: =MAX(0,Ind_IS!F16)*Assumptions!F5 | G17: =MAX(0,Ind_IS!G16)*Assumptions!G5
A18: 净利润 | C18: =Ind_IS!C16-Ind_IS!C17 | D18: =Ind_IS!D16-Ind_IS!D17 | E18: =Ind_IS!E16-Ind_IS!E17 | F18: =Ind_IS!F16-Ind_IS!F17 | G18: =Ind_IS!G16-Ind_IS!G17

Sheet Ind_BS_CF
A1: 智擎行业 · 资产负债表+现金流量表
A2: 单体半厚 | 无 GPU 资产 | 万元
A3: 科目（万元） | B3: 备注 | C3: 2023 | D3: 2024 | E3: 2025 | F3: 2026 | G3: 2027
A4: ── 资产负债表（关键科目）──
A5: 应收账款 | C5: =Ind_IS!C6*Assumptions!C6/365 | D5: =Ind_IS!D6*Assumptions!D6/365 | E5: =Ind_IS!E6*Assumptions!E6/365 | F5: =Ind_IS!F6*Assumptions!F6/365 | G5: =Ind_IS!G6*Assumptions!G6/365
A6: 内部应付（T1+T2） | C6: =(Ind_IS!C9+Ind_IS!C10)*Assumptions!C8/365 | D6: =(Ind_IS!D9+Ind_IS!D10)*Assumptions!D8/365 | E6: =(Ind_IS!E9+Ind_IS!E10)*Assumptions!E8/365 | F6: =(Ind_IS!F9+Ind_IS!F10)*Assumptions!F8/365 | G6: =(Ind_IS!G9+Ind_IS!G10)*Assumptions!G8/365
A7: 应付账款 | B7: 无折旧 | C7: =(Ind_IS!C11+Ind_IS!C13+Ind_IS!C14+Ind_IS!C15)*Assumptions!C7/365 | D7: =(Ind_IS!D11+Ind_IS!D13+Ind_IS!D14+Ind_IS!D15)*Assumptions!D7/365 | E7: =(Ind_IS!E11+Ind_IS!E13+Ind_IS!E14+Ind_IS!E15)*Assumptions!E7/365 | F7: =(Ind_IS!F11+Ind_IS!F13+Ind_IS!F14+Ind_IS!F15)*Assumptions!F7/365 | G7: =(Ind_IS!G11+Ind_IS!G13+Ind_IS!G14+Ind_IS!G15)*Assumptions!G7/365
A8: 递延收益 | C8: =Ind_IS!C6*Assumptions!C78 | D8: =Ind_IS!D6*Assumptions!D78 | E8: =Ind_IS!E6*Assumptions!E78 | F8: =Ind_IS!F6*Assumptions!F78 | G8: =Ind_IS!G6*Assumptions!G78
A9: 负债合计 | C9: =Ind_BS_CF!C7+Ind_BS_CF!C6+Ind_BS_CF!C8 | D9: =Ind_BS_CF!D7+Ind_BS_CF!D6+Ind_BS_CF!D8 | E9: =Ind_BS_CF!E7+Ind_BS_CF!E6+Ind_BS_CF!E8 | F9: =Ind_BS_CF!F7+Ind_BS_CF!F6+Ind_BS_CF!F8 | G9: =Ind_BS_CF!G7+Ind_BS_CF!G6+Ind_BS_CF!G8
A10: 实收资本 | C10: =Assumptions!C71+Assumptions!C58 | D10: =C10+Assumptions!D58 | E10: =D10+Assumptions!E58 | F10: =E10+Assumptions!F58 | G10: =F10+Assumptions!G58
A11: 未分配利润 | C11: =Assumptions!C70+Ind_IS!C18 | D11: =C11+Ind_IS!D18 | E11: =D11+Ind_IS!E18 | F11: =E11+Ind_IS!F18 | G11: =F11+Ind_IS!G18
A12: 货币资金（倒挤） | C12: =Ind_BS_CF!C9+Ind_BS_CF!C10+Ind_BS_CF!C11-Ind_BS_CF!C5 | D12: =Ind_BS_CF!D9+Ind_BS_CF!D10+Ind_BS_CF!D11-Ind_BS_CF!D5 | E12: =Ind_BS_CF!E9+Ind_BS_CF!E10+Ind_BS_CF!E11-Ind_BS_CF!E5 | F12: =Ind_BS_CF!F9+Ind_BS_CF!F10+Ind_BS_CF!F11-Ind_BS_CF!F5 | G12: =Ind_BS_CF!G9+Ind_BS_CF!G10+Ind_BS_CF!G11-Ind_BS_CF!G5
A13: ── 现金流量表（间接法）──
A14: 净利润 | C14: =Ind_IS!C18 | D14: =Ind_IS!D18 | E14: =Ind_IS!E18 | F14: =Ind_IS!F18 | G14: =Ind_IS!G18
A15: 减：应收增加 | C15: =-(Ind_BS_CF!C5-(0)) | D15: =-(Ind_BS_CF!D5-(Ind_BS_CF!C5)) | E15: =-(Ind_BS_CF!E5-(Ind_BS_CF!D5)) | F15: =-(Ind_BS_CF!F5-(Ind_BS_CF!E5)) | G15: =-(Ind_BS_CF!G5-(Ind_BS_CF!F5))
A16: 内部往来净变动 | C16: =(Ind_BS_CF!C6-(0)) | D16: =(Ind_BS_CF!D6-(Ind_BS_CF!C6)) | E16: =(Ind_BS_CF!E6-(Ind_BS_CF!D6)) | F16: =(Ind_BS_CF!F6-(Ind_BS_CF!E6)) | G16: =(Ind_BS_CF!G6-(Ind_BS_CF!F6))
A17: 加：递延增加 | C17: =Ind_BS_CF!C8-(0) | D17: =Ind_BS_CF!D8-(Ind_BS_CF!C8) | E17: =Ind_BS_CF!E8-(Ind_BS_CF!D8) | F17: =Ind_BS_CF!F8-(Ind_BS_CF!E8) | G17: =Ind_BS_CF!G8-(Ind_BS_CF!F8)
A18: 加：应付增加 | C18: =Ind_BS_CF!C7-(0) | D18: =Ind_BS_CF!D7-(Ind_BS_CF!C7) | E18: =Ind_BS_CF!E7-(Ind_BS_CF!D7) | F18: =Ind_BS_CF!F7-(Ind_BS_CF!E7) | G18: =Ind_BS_CF!G7-(Ind_BS_CF!F7)
A19: 经营现金流 | C19: =Ind_BS_CF!C14+Ind_BS_CF!C15+Ind_BS_CF!C16+Ind_BS_CF!C17+Ind_BS_CF!C18 | D19: =Ind_BS_CF!D14+Ind_BS_CF!D15+Ind_BS_CF!D16+Ind_BS_CF!D17+Ind_BS_CF!D18 | E19: =Ind_BS_CF!E14+Ind_BS_CF!E15+Ind_BS_CF!E16+Ind_BS_CF!E17+Ind_BS_CF!E18 | F19: =Ind_BS_CF!F14+Ind_BS_CF!F15+Ind_BS_CF!F16+Ind_BS_CF!F17+Ind_BS_CF!F18 | G19: =Ind_BS_CF!G14+Ind_BS_CF!G15+Ind_BS_CF!G16+Ind_BS_CF!G17+Ind_BS_CF!G18
A20: 筹资：股权注资 | C20: =Assumptions!C58 | D20: =Assumptions!D58 | E20: =Assumptions!E58 | F20: =Assumptions!F58 | G20: =Assumptions!G58
A21: 现金净变动 | C21: =Ind_BS_CF!C19+Ind_BS_CF!C20 | D21: =Ind_BS_CF!D19+Ind_BS_CF!D20 | E21: =Ind_BS_CF!E19+Ind_BS_CF!E20 | F21: =Ind_BS_CF!F19+Ind_BS_CF!F20 | G21: =Ind_BS_CF!G19+Ind_BS_CF!G20
A22: 期末现金（CF） | C22: =14000+Ind_BS_CF!C19+Ind_BS_CF!C20 | D22: =C22+Ind_BS_CF!D19+Ind_BS_CF!D20 | E22: =D22+Ind_BS_CF!E19+Ind_BS_CF!E20 | F22: =E22+Ind_BS_CF!F19+Ind_BS_CF!F20 | G22: =F22+Ind_BS_CF!G19+Ind_BS_CF!G20
A23: ★ CF=BS 差异（应全 0）
A24: CF推导 − BS倒挤 | C24: =Ind_BS_CF!C22-Ind_BS_CF!C12 | D24: =Ind_BS_CF!D22-Ind_BS_CF!D12 | E24: =Ind_BS_CF!E22-Ind_BS_CF!E12 | F24: =Ind_BS_CF!F22-Ind_BS_CF!F12 | G24: =Ind_BS_CF!G22-Ind_BS_CF!G12

Sheet Toc_IS
A1: 智擎互联 · 利润表
A2: 单体 | C端：MAU×转化×ARPPU + 广告 | 万元
A3: 科目（万元） | B3: 备注 | C3: 2023 | D3: 2024 | E3: 2025 | F3: 2026 | G3: 2027
A4: 收入 · C端订阅 | C4: =Assumptions!C31*Assumptions!C32*Assumptions!C33*12 | D4: =Assumptions!D31*Assumptions!D32*Assumptions!D33*12 | E4: =Assumptions!E31*Assumptions!E32*Assumptions!E33*12 | F4: =Assumptions!F31*Assumptions!F32*Assumptions!F33*12 | G4: =Assumptions!G31*Assumptions!G32*Assumptions!G33*12
A5: 收入 · 广告 | C5: =Assumptions!C34 | D5: =Assumptions!D34 | E5: =Assumptions!E34 | F5: =Assumptions!F34 | G5: =Assumptions!G34
A6: 对外收入合计 | C6: =Toc_IS!C4+Toc_IS!C5 | D6: =Toc_IS!D4+Toc_IS!D5 | E6: =Toc_IS!E4+Toc_IS!E5 | F6: =Toc_IS!F4+Toc_IS!F5 | G6: =Toc_IS!G4+Toc_IS!G5
A7: 成本 · 推理+带宽 | B7: 含付云 T3（70%） | C7: =Assumptions!C31*Assumptions!C35*12 | D7: =Assumptions!D31*Assumptions!D35*12 | E7: =Assumptions!E31*Assumptions!E35*12 | F7: =Assumptions!F31*Assumptions!F35*12 | G7: =Assumptions!G31*Assumptions!G35*12
A8: 成本 · T1 license 费 | C8: =Toc_IS!C6*Assumptions!C50 | D8: =Toc_IS!D6*Assumptions!D50 | E8: =Toc_IS!E6*Assumptions!E50 | F8: =Toc_IS!F6*Assumptions!F50 | G8: =Toc_IS!G6*Assumptions!G50
A9: 营业成本合计 | C9: =Toc_IS!C7+Toc_IS!C8 | D9: =Toc_IS!D7+Toc_IS!D8 | E9: =Toc_IS!E7+Toc_IS!E8 | F9: =Toc_IS!F7+Toc_IS!F8 | G9: =Toc_IS!G7+Toc_IS!G8
A10: 毛利润 | C10: =Toc_IS!C6-Toc_IS!C9 | D10: =Toc_IS!D6-Toc_IS!D9 | E10: =Toc_IS!E6-Toc_IS!E9 | F10: =Toc_IS!F6-Toc_IS!F9 | G10: =Toc_IS!G6-Toc_IS!G9
A11: 研发费用 | B11: ×70万 | C11: =Assumptions!C38*70 | D11: =Assumptions!D38*70 | E11: =Assumptions!E38*70 | F11: =Assumptions!F38*70 | G11: =Assumptions!G38*70
A12: 销售费用 · 获客 | B12: 新增用户×CAC | C12: =(Assumptions!C31-0)*Assumptions!C37*Assumptions!C36 | D12: =(Assumptions!D31-Assumptions!C31)*Assumptions!C37*Assumptions!D36 | E12: =(Assumptions!E31-Assumptions!D31)*Assumptions!C37*Assumptions!E36 | F12: =(Assumptions!F31-Assumptions!E31)*Assumptions!C37*Assumptions!F36 | G12: =(Assumptions!G31-Assumptions!F31)*Assumptions!C37*Assumptions!G36
A13: 销售费用合计 | C13: =Toc_IS!C12+Assumptions!C39*55 | D13: =Toc_IS!D12+Assumptions!D39*55 | E13: =Toc_IS!E12+Assumptions!E39*55 | F13: =Toc_IS!F12+Assumptions!F39*55 | G13: =Toc_IS!G12+Assumptions!G39*55
A14: 管理费用 | B14: ×55万 | C14: =Assumptions!C40*55 | D14: =Assumptions!D40*55 | E14: =Assumptions!E40*55 | F14: =Assumptions!F40*55 | G14: =Assumptions!G40*55
A15: EBIT | C15: =Toc_IS!C10-Toc_IS!C11-Toc_IS!C13-Toc_IS!C14 | D15: =Toc_IS!D10-Toc_IS!D11-Toc_IS!D13-Toc_IS!D14 | E15: =Toc_IS!E10-Toc_IS!E11-Toc_IS!E13-Toc_IS!E14 | F15: =Toc_IS!F10-Toc_IS!F11-Toc_IS!F13-Toc_IS!F14 | G15: =Toc_IS!G10-Toc_IS!G11-Toc_IS!G13-Toc_IS!G14
A16: 所得税 | C16: =MAX(0,Toc_IS!C15)*Assumptions!C5 | D16: =MAX(0,Toc_IS!D15)*Assumptions!D5 | E16: =MAX(0,Toc_IS!E15)*Assumptions!E5 | F16: =MAX(0,Toc_IS!F15)*Assumptions!F5 | G16: =MAX(0,Toc_IS!G15)*Assumptions!G5
A17: 净利润 | B17: 归母80% | C17: =Toc_IS!C15-Toc_IS!C16 | D17: =Toc_IS!D15-Toc_IS!D16 | E17: =Toc_IS!E15-Toc_IS!E16 | F17: =Toc_IS!F15-Toc_IS!F16 | G17: =Toc_IS!G15-Toc_IS!G16

Sheet Toc_BS_CF
A1: 智擎互联 · 资产负债表+现金流量表
A2: 单体半厚 | 母公司持股80% | 万元
A3: 科目（万元） | B3: 备注 | C3: 2023 | D3: 2024 | E3: 2025 | F3: 2026 | G3: 2027
A4: ── 资产负债表（关键科目）──
A5: 应收账款 | B5: 广告主账期 | C5: =Toc_IS!C6*Assumptions!C6/365 | D5: =Toc_IS!D6*Assumptions!D6/365 | E5: =Toc_IS!E6*Assumptions!E6/365 | F5: =Toc_IS!F6*Assumptions!F6/365 | G5: =Toc_IS!G6*Assumptions!G6/365
A6: 内部应付（T3+T1） | B6: 含在途，全挂 | C6: =(Assumptions!C31*Assumptions!C35*12*Assumptions!C52+Toc_IS!C8)*Assumptions!C8/365 | D6: =(Assumptions!D31*Assumptions!D35*12*Assumptions!D52+Toc_IS!D8)*Assumptions!D8/365 | E6: =(Assumptions!E31*Assumptions!E35*12*Assumptions!E52+Toc_IS!E8)*Assumptions!E8/365 | F6: =(Assumptions!F31*Assumptions!F35*12*Assumptions!F52+Toc_IS!F8)*Assumptions!F8/365 | G6: =(Assumptions!G31*Assumptions!G35*12*Assumptions!G52+Toc_IS!G8)*Assumptions!G8/365
A7: 应付账款 | C7: =(Toc_IS!C9+Toc_IS!C11+Toc_IS!C13+Toc_IS!C14)*Assumptions!C7/365 | D7: =(Toc_IS!D9+Toc_IS!D11+Toc_IS!D13+Toc_IS!D14)*Assumptions!D7/365 | E7: =(Toc_IS!E9+Toc_IS!E11+Toc_IS!E13+Toc_IS!E14)*Assumptions!E7/365 | F7: =(Toc_IS!F9+Toc_IS!F11+Toc_IS!F13+Toc_IS!F14)*Assumptions!F7/365 | G7: =(Toc_IS!G9+Toc_IS!G11+Toc_IS!G13+Toc_IS!G14)*Assumptions!G7/365
A8: 递延收益 | B8: 订阅年费预收 | C8: =Toc_IS!C4*Assumptions!C79 | D8: =Toc_IS!D4*Assumptions!D79 | E8: =Toc_IS!E4*Assumptions!E79 | F8: =Toc_IS!F4*Assumptions!F79 | G8: =Toc_IS!G4*Assumptions!G79
A9: 负债合计 | C9: =Toc_BS_CF!C7+Toc_BS_CF!C6+Toc_BS_CF!C8 | D9: =Toc_BS_CF!D7+Toc_BS_CF!D6+Toc_BS_CF!D8 | E9: =Toc_BS_CF!E7+Toc_BS_CF!E6+Toc_BS_CF!E8 | F9: =Toc_BS_CF!F7+Toc_BS_CF!F6+Toc_BS_CF!F8 | G9: =Toc_BS_CF!G7+Toc_BS_CF!G6+Toc_BS_CF!G8
A10: 实收资本 | B10: 母80%+战投20% | C10: =Assumptions!C73+Assumptions!C59 | D10: =C10+Assumptions!D59 | E10: =D10+Assumptions!E59 | F10: =E10+Assumptions!F59 | G10: =F10+Assumptions!G59
A11: 未分配利润 | C11: =Assumptions!C72+Toc_IS!C17 | D11: =C11+Toc_IS!D17 | E11: =D11+Toc_IS!E17 | F11: =E11+Toc_IS!F17 | G11: =F11+Toc_IS!G17
A12: 货币资金（倒挤） | C12: =Toc_BS_CF!C9+Toc_BS_CF!C10+Toc_BS_CF!C11-Toc_BS_CF!C5 | D12: =Toc_BS_CF!D9+Toc_BS_CF!D10+Toc_BS_CF!D11-Toc_BS_CF!D5 | E12: =Toc_BS_CF!E9+Toc_BS_CF!E10+Toc_BS_CF!E11-Toc_BS_CF!E5 | F12: =Toc_BS_CF!F9+Toc_BS_CF!F10+Toc_BS_CF!F11-Toc_BS_CF!F5 | G12: =Toc_BS_CF!G9+Toc_BS_CF!G10+Toc_BS_CF!G11-Toc_BS_CF!G5
A13: ── 现金流量表（间接法）──
A14: 净利润 | C14: =Toc_IS!C17 | D14: =Toc_IS!D17 | E14: =Toc_IS!E17 | F14: =Toc_IS!F17 | G14: =Toc_IS!G17
A15: 减：应收增加 | C15: =-(Toc_BS_CF!C5-(0)) | D15: =-(Toc_BS_CF!D5-(Toc_BS_CF!C5)) | E15: =-(Toc_BS_CF!E5-(Toc_BS_CF!D5)) | F15: =-(Toc_BS_CF!F5-(Toc_BS_CF!E5)) | G15: =-(Toc_BS_CF!G5-(Toc_BS_CF!F5))
A16: 内部往来净变动 | C16: =(Toc_BS_CF!C6-(0)) | D16: =(Toc_BS_CF!D6-(Toc_BS_CF!C6)) | E16: =(Toc_BS_CF!E6-(Toc_BS_CF!D6)) | F16: =(Toc_BS_CF!F6-(Toc_BS_CF!E6)) | G16: =(Toc_BS_CF!G6-(Toc_BS_CF!F6))
A17: 加：递延增加 | C17: =Toc_BS_CF!C8-(0) | D17: =Toc_BS_CF!D8-(Toc_BS_CF!C8) | E17: =Toc_BS_CF!E8-(Toc_BS_CF!D8) | F17: =Toc_BS_CF!F8-(Toc_BS_CF!E8) | G17: =Toc_BS_CF!G8-(Toc_BS_CF!F8)
A18: 加：应付增加 | C18: =Toc_BS_CF!C7-(0) | D18: =Toc_BS_CF!D7-(Toc_BS_CF!C7) | E18: =Toc_BS_CF!E7-(Toc_BS_CF!D7) | F18: =Toc_BS_CF!F7-(Toc_BS_CF!E7) | G18: =Toc_BS_CF!G7-(Toc_BS_CF!F7)
A19: 经营现金流 | C19: =Toc_BS_CF!C14+Toc_BS_CF!C15+Toc_BS_CF!C16+Toc_BS_CF!C17+Toc_BS_CF!C18 | D19: =Toc_BS_CF!D14+Toc_BS_CF!D15+Toc_BS_CF!D16+Toc_BS_CF!D17+Toc_BS_CF!D18 | E19: =Toc_BS_CF!E14+Toc_BS_CF!E15+Toc_BS_CF!E16+Toc_BS_CF!E17+Toc_BS_CF!E18 | F19: =Toc_BS_CF!F14+Toc_BS_CF!F15+Toc_BS_CF!F16+Toc_BS_CF!F17+Toc_BS_CF!F18 | G19: =Toc_BS_CF!G14+Toc_BS_CF!G15+Toc_BS_CF!G16+Toc_BS_CF!G17+Toc_BS_CF!G18
A20: 筹资：股权注资（含战投） | C20: =Assumptions!C59 | D20: =Assumptions!D59 | E20: =Assumptions!E59 | F20: =Assumptions!F59 | G20: =Assumptions!G59
A21: 现金净变动 | C21: =Toc_BS_CF!C19+Toc_BS_CF!C20 | D21: =Toc_BS_CF!D19+Toc_BS_CF!D20 | E21: =Toc_BS_CF!E19+Toc_BS_CF!E20 | F21: =Toc_BS_CF!F19+Toc_BS_CF!F20 | G21: =Toc_BS_CF!G19+Toc_BS_CF!G20
A22: 期末现金（CF） | C22: =7000+Toc_BS_CF!C19+Toc_BS_CF!C20 | D22: =C22+Toc_BS_CF!D19+Toc_BS_CF!D20 | E22: =D22+Toc_BS_CF!E19+Toc_BS_CF!E20 | F22: =E22+Toc_BS_CF!F19+Toc_BS_CF!F20 | G22: =F22+Toc_BS_CF!G19+Toc_BS_CF!G20
A23: ★ CF=BS 差异（应全 0）
A24: CF推导 − BS倒挤 | C24: =Toc_BS_CF!C22-Toc_BS_CF!C12 | D24: =Toc_BS_CF!D22-Toc_BS_CF!D12 | E24: =Toc_BS_CF!E22-Toc_BS_CF!E12 | F24: =Toc_BS_CF!F22-Toc_BS_CF!F12 | G24: =Toc_BS_CF!G22-Toc_BS_CF!G12

Sheet HoldCo_IS
A1: 智擎研究院 · 利润表
A2: 单体 | 全关联收入，无对外收入 | 万元
A3: 科目（万元） | B3: 备注 | C3: 2023 | D3: 2024 | E3: 2025 | F3: 2026 | G3: 2027
A4: 关联收入 · T1 模型 license | B4: 三家子公司对外收入×费率 | C4: =Cloud_IS!C4*Assumptions!C48+Ind_IS!C6*Assumptions!C49+Toc_IS!C6*Assumptions!C50 | D4: =Cloud_IS!D4*Assumptions!D48+Ind_IS!D6*Assumptions!D49+Toc_IS!D6*Assumptions!D50 | E4: =Cloud_IS!E4*Assumptions!E48+Ind_IS!E6*Assumptions!E49+Toc_IS!E6*Assumptions!E50 | F4: =Cloud_IS!F4*Assumptions!F48+Ind_IS!F6*Assumptions!F49+Toc_IS!F6*Assumptions!F50 | G4: =Cloud_IS!G4*Assumptions!G48+Ind_IS!G6*Assumptions!G49+Toc_IS!G6*Assumptions!G50
A5: 关联收入 · T2 定制研发服务 | B5: 行业子公司 | C5: =Assumptions!C51 | D5: =Assumptions!D51 | E5: =Assumptions!E51 | F5: =Assumptions!F51 | G5: =Assumptions!G51
A6: 营业收入合计 | C6: =HoldCo_IS!C4+HoldCo_IS!C5 | D6: =HoldCo_IS!D4+HoldCo_IS!D5 | E6: =HoldCo_IS!E4+HoldCo_IS!E5 | F6: =HoldCo_IS!F4+HoldCo_IS!F5 | G6: =HoldCo_IS!G4+HoldCo_IS!G5
A7: 营业成本 | B7: 研究院无直接 COGS | C7: 0 | D7: 0 | E7: 0 | F7: 0 | G7: 0
A8: 毛利润 | C8: =HoldCo_IS!C6-HoldCo_IS!C7 | D8: =HoldCo_IS!D6-HoldCo_IS!D7 | E8: =HoldCo_IS!E6-HoldCo_IS!E7 | F8: =HoldCo_IS!F6-HoldCo_IS!F7 | G8: =HoldCo_IS!G6-HoldCo_IS!G7
A9: 研发费用 | B9: 编制+训练折旧+其他 | C9: =Assumptions!C42*Assumptions!C43+Capex_Dep!C22+Assumptions!C44 | D9: =Assumptions!D42*Assumptions!D43+Capex_Dep!D22+Assumptions!D44 | E9: =Assumptions!E42*Assumptions!E43+Capex_Dep!E22+Assumptions!E44 | F9: =Assumptions!F42*Assumptions!F43+Capex_Dep!F22+Assumptions!F44 | G9: =Assumptions!G42*Assumptions!G43+Capex_Dep!G22+Assumptions!G44
A10: 销售费用 | C10: 0 | D10: 0 | E10: 0 | F10: 0 | G10: 0
A11: 管理费用 | C11: =Assumptions!C45*Assumptions!C46 | D11: =Assumptions!D45*Assumptions!D46 | E11: =Assumptions!E45*Assumptions!E46 | F11: =Assumptions!F45*Assumptions!F46 | G11: =Assumptions!G45*Assumptions!G46
A12: EBIT | C12: =HoldCo_IS!C8-HoldCo_IS!C9-HoldCo_IS!C10-HoldCo_IS!C11 | D12: =HoldCo_IS!D8-HoldCo_IS!D9-HoldCo_IS!D10-HoldCo_IS!D11 | E12: =HoldCo_IS!E8-HoldCo_IS!E9-HoldCo_IS!E10-HoldCo_IS!E11 | F12: =HoldCo_IS!F8-HoldCo_IS!F9-HoldCo_IS!F10-HoldCo_IS!F11 | G12: =HoldCo_IS!G8-HoldCo_IS!G9-HoldCo_IS!G10-HoldCo_IS!G11
A13: 所得税（亏损不确认） | C13: =MAX(0,HoldCo_IS!C12)*Assumptions!C5 | D13: =MAX(0,HoldCo_IS!D12)*Assumptions!D5 | E13: =MAX(0,HoldCo_IS!E12)*Assumptions!E5 | F13: =MAX(0,HoldCo_IS!F12)*Assumptions!F5 | G13: =MAX(0,HoldCo_IS!G12)*Assumptions!G5
A14: 净利润 | C14: =HoldCo_IS!C12-HoldCo_IS!C13 | D14: =HoldCo_IS!D12-HoldCo_IS!D13 | E14: =HoldCo_IS!E12-HoldCo_IS!E13 | F14: =HoldCo_IS!F12-HoldCo_IS!F13 | G14: =HoldCo_IS!G12-HoldCo_IS!G13

Sheet HoldCo_BS
A1: 智擎研究院 · 资产负债表
A2: 单体 | 现金=倒挤项 → 结构性平衡 | 万元
A3: 科目（万元） | B3: 备注 | C3: 2023 | D3: 2024 | E3: 2025 | F3: 2026 | G3: 2027
A4: 应收账款 | B4: 无对外收入，应收为 0 | C4: 0 | D4: 0 | E4: 0 | F4: 0 | G4: 0
A5: 内部应收（关联往来） | B5: T1+T2 × 60天 | C5: =(HoldCo_IS!C4+HoldCo_IS!C5)*Assumptions!C8/365 | D5: =(HoldCo_IS!D4+HoldCo_IS!D5)*Assumptions!D8/365 | E5: =(HoldCo_IS!E4+HoldCo_IS!E5)*Assumptions!E8/365 | F5: =(HoldCo_IS!F4+HoldCo_IS!F5)*Assumptions!F8/365 | G5: =(HoldCo_IS!G4+HoldCo_IS!G5)*Assumptions!G8/365
A6: 固定资产 · GPU 净值 | B6: 训练算力 | C6: =Capex_Dep!C23 | D6: =Capex_Dep!D23 | E6: =Capex_Dep!E23 | F6: =Capex_Dep!F23 | G6: =Capex_Dep!G23
A7: 长期股权投资 | B7: 成本法：期初+对子公司注资 | C7: =Assumptions!C76+(Assumptions!C57+Assumptions!C58+Assumptions!C59*0.8) | D7: =C7+(Assumptions!D57+Assumptions!D58+Assumptions!D59*0.8) | E7: =D7+(Assumptions!E57+Assumptions!E58+Assumptions!E59*0.8) | F7: =E7+(Assumptions!F57+Assumptions!F58+Assumptions!F59*0.8) | G7: =F7+(Assumptions!G57+Assumptions!G58+Assumptions!G59*0.8)
A8: 非现金资产合计 | B8: （辅助行） | C8: =HoldCo_BS!C4+HoldCo_BS!C5+HoldCo_BS!C6+HoldCo_BS!C7 | D8: =HoldCo_BS!D4+HoldCo_BS!D5+HoldCo_BS!D6+HoldCo_BS!D7 | E8: =HoldCo_BS!E4+HoldCo_BS!E5+HoldCo_BS!E6+HoldCo_BS!E7 | F8: =HoldCo_BS!F4+HoldCo_BS!F5+HoldCo_BS!F6+HoldCo_BS!F7 | G8: =HoldCo_BS!G4+HoldCo_BS!G5+HoldCo_BS!G6+HoldCo_BS!G7
A10: 应付账款 | B10: 现金成本×DPO | C10: =(HoldCo_IS!C7+HoldCo_IS!C9+HoldCo_IS!C10+HoldCo_IS!C11-Capex_Dep!C22)*Assumptions!C7/365 | D10: =(HoldCo_IS!D7+HoldCo_IS!D9+HoldCo_IS!D10+HoldCo_IS!D11-Capex_Dep!D22)*Assumptions!D7/365 | E10: =(HoldCo_IS!E7+HoldCo_IS!E9+HoldCo_IS!E10+HoldCo_IS!E11-Capex_Dep!E22)*Assumptions!E7/365 | F10: =(HoldCo_IS!F7+HoldCo_IS!F9+HoldCo_IS!F10+HoldCo_IS!F11-Capex_Dep!F22)*Assumptions!F7/365 | G10: =(HoldCo_IS!G7+HoldCo_IS!G9+HoldCo_IS!G10+HoldCo_IS!G11-Capex_Dep!G22)*Assumptions!G7/365
A11: 内部应付 | C11: 0 | D11: 0 | E11: 0 | F11: 0 | G11: 0
A12: 递延收益 | C12: 0 | D12: 0 | E12: 0 | F12: 0 | G12: 0
A13: 负债合计 | C13: =HoldCo_BS!C10+HoldCo_BS!C11+HoldCo_BS!C12 | D13: =HoldCo_BS!D10+HoldCo_BS!D11+HoldCo_BS!D12 | E13: =HoldCo_BS!E10+HoldCo_BS!E11+HoldCo_BS!E12 | F13: =HoldCo_BS!F10+HoldCo_BS!F11+HoldCo_BS!F12 | G13: =HoldCo_BS!G10+HoldCo_BS!G11+HoldCo_BS!G12
A14: 实收资本 | C14: =Assumptions!C67+Assumptions!C56 | D14: =C14+Assumptions!D56 | E14: =D14+Assumptions!E56 | F14: =E14+Assumptions!F56 | G14: =F14+Assumptions!G56
A15: 未分配利润 | B15: 期初+NI，无分红 | C15: =Assumptions!C66+HoldCo_IS!C14 | D15: =C15+HoldCo_IS!D14 | E15: =D15+HoldCo_IS!E14 | F15: =E15+HoldCo_IS!F14 | G15: =F15+HoldCo_IS!G14
A16: 所有者权益合计 | C16: =HoldCo_BS!C14+HoldCo_BS!C15 | D16: =HoldCo_BS!D14+HoldCo_BS!D15 | E16: =HoldCo_BS!E14+HoldCo_BS!E15 | F16: =HoldCo_BS!F14+HoldCo_BS!F15 | G16: =HoldCo_BS!G14+HoldCo_BS!G15
A17: 负债+权益合计 | C17: =HoldCo_BS!C13+HoldCo_BS!C16 | D17: =HoldCo_BS!D13+HoldCo_BS!D16 | E17: =HoldCo_BS!E13+HoldCo_BS!E16 | F17: =HoldCo_BS!F13+HoldCo_BS!F16 | G17: =HoldCo_BS!G13+HoldCo_BS!G16
A18: 货币资金（倒挤） | B18: 负债+权益−非现金资产 | C18: =HoldCo_BS!C17-HoldCo_BS!C8 | D18: =HoldCo_BS!D17-HoldCo_BS!D8 | E18: =HoldCo_BS!E17-HoldCo_BS!E8 | F18: =HoldCo_BS!F17-HoldCo_BS!F8 | G18: =HoldCo_BS!G17-HoldCo_BS!G8
